Workbook

Sheet Mercado
B2: CONSEIL OLÉICOLE INTERNATIONAL (NOV 2025)
B3: INTERNATIONAL OLIVE COUNCIL (NOV 2025)
B4: HUILES D'OLIVE - OLIVE OILS
B5: Unidad: kt
C7: 2013/14 | D7: 2014/15 | E7: 2015/16 | F7: 2016/17 | G7: 2017/18 | H7: 2018/19 | I7: 2019/20 | J7: 2020/21 | K7: 2021/22 | L7: 2022/23 | M7: 2023/24 | N7: 2024/25 | O7: 2025/26
N8: (prov.) | O8: (prev.)
C9: (24) | D9: (25) | E9: (26) | F9: (27) | G9: (28) | H9: (29) | I9: (30) | J9: (31) | K9: (32) | L9: (33) | M9: (34) | N9: (35) | O9: (36)
A10: Uruguay | B10: Importación | C10: 1 | D10: 1 | E10: 1 | F10: 1 | G10: 1 | H10: 1 | I10: 1 | J10: 1 | K10: 1 | L10: 0.5 | M10: 0.5 | N10: 1 | O10: 1
A11: Uruguay | B11: Exportación | C11: 0 | D11: 0 | E11: 0 | F11: 0 | G11: 0 | H11: 0 | I11: 1 | J11: 0.5 | K11: 0.5 | L11: 0.5 | M11: 0.5 | N11: 0 | O11: 0
A12: Uruguay | B12: Produccion | C12: 0.5 | D12: 0.5 | E12: 0.5 | F12: 0.5 | G12: 1 | H12: 0.5 | I12: 2.5 | J12: 0.5 | K12: 1.5 | L12: 1.5 | M12: 2 | N12: 0.5 | O12: 0.5
A13: Uruguay | B13: Consumo | C13: 1.5 | D13: 1.5 | E13: 1.5 | F13: 1.5 | G13: 1.5 | H13: 2 | I13: 2 | J13: 1.5 | K13: 1.5 | L13: 2 | M13: 2 | N13: 1.5 | O13: 1.5
C17: Unidad | D17: TAM | E17: SAM | F17: MES | G17: Meses | H17: SOM | I17: Litros | J17: Bid. X 5 | K17: MES
C18: kt | D18: 1.5 | E18: =D18*0.5 -> 0.75 | G18: 12 | H18: 0.02 | I18: =H18*$E$20 -> 16380 | J18: =I18/5 -> 3276 | K18: =J18/12 -> 273
C19: T | D19: =D18*1000 -> 1500 | E19: =D19*0.5 -> 750 | G19: 24 | H19: 0.05 | I19: =H19*$E$20 -> 40950 | J19: =I19/5 -> 8190 | K19: =J19/12 -> 682.5
C20: Lts. | D20: =D19*Valores!$B$4 -> 1638000 | E20: =D20*0.5 -> 819000 | F20: =E20/12 -> 68250 | G20: 36 | H20: 0.1 | I20: =H20*$E$20 -> 81900 | J20: =I20/5 -> 16380 | K20: =J20/12 -> 1365
C22: TAM | D22: Total Addressable Market | F22: Mercado total posible
C23: SAM | D23: Serviceable Available Market | F23: Mercado disponible
C24: SOM | D24: Serviceable Obtainable Market | F24: Mercado objetivo

Sheet Objetivo
A1: Año | B1: Mes | C1: SOM | D1: C. Mensual | E1: Lts / Mes | F1: Lts. Ac. | G1: B5 / Mes | H1: Vtas. Netas | I1: CMV | J1: Res. Bruto | K1: Logística | L1: Admin. | M1: Mktg | N1: Comercial | O1: Financiero | P1: COT | Q1: % COT | R1: EBITDA | S1: IRAE | T1: Res. Neto | U1: % Venta Neta
A2: 2026 | B2: Jul | C2: =E2/Mercado!F20 -> 0.0036630037 | E2: =G2*5 -> 250 | F2: =E2 -> 250 | G2: 50 | H2: =G2*Valores!$D$7 -> 181363.64 | I2: =G2*Valores!$D$9 -> 112500 | J2: =H2-I2 -> 68863.636 | K2: =H2*'P&L'!$B$22 -> 9068.1818 | L2: =H2*'P&L'!$B$29 -> 3627.2727 | M2: =H2*'P&L'!$B$35 -> 4534.0909 | N2: =H2*'P&L'!$B$41 -> 14509.091 | O2: =H2*'P&L'!$B$46 -> 9068.1818 | P2: =SUM(K2:O2) -> 40806.818 | Q2: =P2/H2 -> 0.225 | R2: =J2-P2 -> 28056.818 | S2: =R2*0.25 -> 7014.2045 | T2: =R2-S2 -> 21042.614 | U2: =T2/H2 -> 0.11602444
A3: 2026 | B3: Ago | C3: =C2*D3 -> 0.0045787546 | D3: 1.25 | E3: =E2*D3 -> 312.5 | F3: =F2+E3 -> 562.5 | G3: =E3/5 -> 62.5 | H3: =G3*Valores!$D$7 -> 226704.55 | I3: =G3*Valores!$D$9 -> 140625 | J3: =H3-I3 -> 86079.545 | K3: =H3*'P&L'!$B$22 -> 11335.227 | L3: =H3*'P&L'!$B$29 -> 4534.0909 | M3: =H3*'P&L'!$B$35 -> 5667.6136 | N3: =H3*'P&L'!$B$41 -> 18136.364 | O3: =H3*'P&L'!$B$46 -> 11335.227 | P3: =SUM(K3:O3) -> 51008.523 | Q3: =P3/H3 -> 0.225 | R3: =J3-P3 -> 35071.023 | S3: =R3*0.25 -> 8767.7557 | T3: =R3-S3 -> 26303.267 | U3: =T3/H3 -> 0.11602444
A4: 2026 | B4: Set | C4: =C3*D4 -> 0.0056318681 | D4: 1.23 | E4: =E3*D4 -> 384.375 | F4: =F3+E4 -> 946.875 | G4: =E4/5 -> 76.875 | H4: =G4*Valores!$D$7 -> 278846.59 | I4: =G4*Valores!$D$9 -> 172968.75 | J4: =H4-I4 -> 105877.84 | K4: =H4*'P&L'!$B$22 -> 13942.33 | L4: =H4*'P&L'!$B$29 -> 5576.9318 | M4: =H4*'P&L'!$B$35 -> 6971.1648 | N4: =H4*'P&L'!$B$41 -> 22307.727 | O4: =H4*'P&L'!$B$46 -> 13942.33 | P4: =SUM(K4:O4) -> 62740.483 | Q4: =P4/H4 -> 0.225 | R4: =J4-P4 -> 43137.358 | S4: =R4*0.25 -> 10784.339 | T4: =R4-S4 -> 32353.018 | U4: =T4/H4 -> 0.11602444
A5: 2026 | B5: Oct | C5: =C4*D5 -> 0.0064766484 | D5: 1.15 | E5: =E4*D5 -> 442.03125 | F5: =F4+E5 -> 1388.9062 | G5: =E5/5 -> 88.40625 | H5: =G5*Valores!$D$7 -> 320673.58 | I5: =G5*Valores!$D$9 -> 198914.06 | J5: =H5-I5 -> 121759.52 | K5: =H5*'P&L'!$B$22 -> 16033.679 | L5: =H5*'P&L'!$B$29 -> 6413.4716 | M5: =H5*'P&L'!$B$35 -> 8016.8395 | N5: =H5*'P&L'!$B$41 -> 25653.886 | O5: =H5*'P&L'!$B$46 -> 16033.679 | P5: =SUM(K5:O5) -> 72151.555 | Q5: =P5/H5 -> 0.225 | R5: =J5-P5 -> 49607.962 | S5: =R5*0.25 -> 12401.99 | T5: =R5-S5 -> 37205.971 | U5: =T5/H5 -> 0.11602444
A6: 2026 | B6: Nov | C6: =C5*D6 -> 0.0080958104 | D6: 1.25 | E6: =E5*D6 -> 552.53906 | F6: =F5+E6 -> 1941.4453 | G6: =E6/5 -> 110.50781 | H6: =G6*Valores!$D$7 -> 400841.97 | I6: =G6*Valores!$D$9 -> 248642.58 | J6: =H6-I6 -> 152199.4 | K6: =H6*'P&L'!$B$22 -> 20042.099 | L6: =H6*'P&L'!$B$29 -> 8016.8395 | M6: =H6*'P&L'!$B$35 -> 10021.049 | N6: =H6*'P&L'!$B$41 -> 32067.358 | O6: =H6*'P&L'!$B$46 -> 20042.099 | P6: =SUM(K6:O6) -> 90189.444 | Q6: =P6/H6 -> 0.225 | R6: =J6-P6 -> 62009.952 | S6: =R6*0.25 -> 15502.488 | T6: =R6-S6 -> 46507.464 | U6: =T6/H6 -> 0.11602444
A7: 2026 | B7: Dic | C7: =C6*D7 -> 0.010524554 | D7: 1.3 | E7: =E6*D7 -> 718.30078 | F7: =F6+E7 -> 2659.7461 | G7: =E7/5 -> 143.66016 | H7: =G7*Valores!$D$7 -> 521094.57 | I7: =G7*Valores!$D$9 -> 323235.35 | J7: =H7-I7 -> 197859.22 | K7: =H7*'P&L'!$B$22 -> 26054.728 | L7: =H7*'P&L'!$B$29 -> 10421.891 | M7: =H7*'P&L'!$B$35 -> 13027.364 | N7: =H7*'P&L'!$B$41 -> 41687.565 | O7: =H7*'P&L'!$B$46 -> 26054.728 | P7: =SUM(K7:O7) -> 117246.28 | Q7: =P7/H7 -> 0.225 | R7: =J7-P7 -> 80612.938 | S7: =R7*0.25 -> 20153.234 | T7: =R7-S7 -> 60459.703 | U7: =T7/H7 -> 0.11602444
A8: 2027 | B8: Ene | C8: =C7*D8 -> 0.011366518 | D8: 1.08 | E8: =E7*D8 -> 775.76484 | F8: =F7+E8 -> 3435.5109 | G8: =E8/5 -> 155.15297 | H8: =G8*Valores!$D$7 -> 562782.13 | I8: =G8*Valores!$D$9 -> 349094.18 | J8: =H8-I8 -> 213687.95 | K8: =H8*'P&L'!$B$22 -> 28139.107 | L8: =H8*'P&L'!$B$29 -> 11255.643 | M8: =H8*'P&L'!$B$35 -> 14069.553 | N8: =H8*'P&L'!$B$41 -> 45022.571 | O8: =H8*'P&L'!$B$46 -> 28139.107 | P8: =SUM(K8:O8) -> 126625.98 | Q8: =P8/H8 -> 0.225 | R8: =J8-P8 -> 87061.973 | S8: =R8*0.25 -> 21765.493 | T8: =R8-S8 -> 65296.48 | U8: =T8/H8 -> 0.11602444
A9: 2027 | B9: Feb | C9: =C8*D9 -> 0.012389504 | D9: 1.09 | E9: =E8*D9 -> 845.58368 | F9: =F8+E9 -> 4281.0946 | G9: =E9/5 -> 169.11674 | H9: =G9*Valores!$D$7 -> 613432.52 | I9: =G9*Valores!$D$9 -> 380512.66 | J9: =H9-I9 -> 232919.87 | K9: =H9*'P&L'!$B$22 -> 30671.626 | L9: =H9*'P&L'!$B$29 -> 12268.65 | M9: =H9*'P&L'!$B$35 -> 15335.813 | N9: =H9*'P&L'!$B$41 -> 49074.602 | O9: =H9*'P&L'!$B$46 -> 30671.626 | P9: =SUM(K9:O9) -> 138022.32 | Q9: =P9/H9 -> 0.225 | R9: =J9-P9 -> 94897.55 | S9: =R9*0.25 -> 23724.388 | T9: =R9-S9 -> 71173.163 | U9: =T9/H9 -> 0.11602444
A10: 2027 | B10: Mar | C10: =C9*D10 -> 0.013380665 | D10: 1.08 | E10: =E9*D10 -> 913.23037 | F10: =F9+E10 -> 5194.325 | G10: =E10/5 -> 182.64607 | H10: =G10*Valores!$D$7 -> 662507.13 | I10: =G10*Valores!$D$9 -> 410953.67 | J10: =H10-I10 -> 251553.46 | K10: =H10*'P&L'!$B$22 -> 33125.356 | L10: =H10*'P&L'!$B$29 -> 13250.143 | M10: =H10*'P&L'!$B$35 -> 16562.678 | N10: =H10*'P&L'!$B$41 -> 53000.57 | O10: =H10*'P&L'!$B$46 -> 33125.356 | P10: =SUM(K10:O10) -> 149064.1 | Q10: =P10/H10 -> 0.225 | R10: =J10-P10 -> 102489.35 | S10: =R10*0.25 -> 25622.339 | T10: =R10-S10 -> 76867.016 | U10: =T10/H10 -> 0.11602444
A11: 2027 | B11: Abr | C11: =C10*D11 -> 0.014584925 | D11: 1.09 | E11: =E10*D11 -> 995.42111 | F11: =F10+E11 -> 6189.7461 | G11: =E11/5 -> 199.08422 | H11: =G11*Valores!$D$7 -> 722132.77 | I11: =G11*Valores!$D$9 -> 447939.5 | J11: =H11-I11 -> 274193.27 | K11: =H11*'P&L'!$B$22 -> 36106.638 | L11: =H11*'P&L'!$B$29 -> 14442.655 | M11: =H11*'P&L'!$B$35 -> 18053.319 | N11: =H11*'P&L'!$B$41 -> 57770.621 | O11: =H11*'P&L'!$B$46 -> 36106.638 | P11: =SUM(K11:O11) -> 162479.87 | Q11: =P11/H11 -> 0.225 | R11: =J11-P11 -> 111713.4 | S11: =R11*0.25 -> 27928.349 | T11: =R11-S11 -> 83785.047 | U11: =T11/H11 -> 0.11602444
A12: 2027 | B12: May | C12: =C11*D12 -> 0.016043417 | D12: 1.1 | E12: =E11*D12 -> 1094.9632 | F12: =F11+E12 -> 7284.7093 | G12: =E12/5 -> 218.99264 | H12: =G12*Valores!$D$7 -> 794346.04 | I12: =G12*Valores!$D$9 -> 492733.45 | J12: =H12-I12 -> 301612.6 | K12: =H12*'P&L'!$B$22 -> 39717.302 | L12: =H12*'P&L'!$B$29 -> 15886.921 | M12: =H12*'P&L'!$B$35 -> 19858.651 | N12: =H12*'P&L'!$B$41 -> 63547.684 | O12: =H12*'P&L'!$B$46 -> 39717.302 | P12: =SUM(K12:O12) -> 178727.86 | Q12: =P12/H12 -> 0.225 | R12: =J12-P12 -> 122884.74 | S12: =R12*0.25 -> 30721.184 | T12: =R12-S12 -> 92163.552 | U12: =T12/H12 -> 0.11602444
A13: 2027 | B13: Jun | C13: =C12*D13 -> 0.017808193 | D13: 1.11 | E13: =E12*D13 -> 1215.4092 | F13: =F12+E13 -> 8500.1185 | G13: =E13/5 -> 243.08183 | H13: =G13*Valores!$D$7 -> 881724.11 | I13: =G13*Valores!$D$9 -> 546934.13 | J13: =H13-I13 -> 334789.98 | K13: =H13*'P&L'!$B$22 -> 44086.205 | L13: =H13*'P&L'!$B$29 -> 17634.482 | M13: =H13*'P&L'!$B$35 -> 22043.103 | N13: =H13*'P&L'!$B$41 -> 70537.929 | O13: =H13*'P&L'!$B$46 -> 44086.205 | P13: =SUM(K13:O13) -> 198387.92 | Q13: =P13/H13 -> 0.225 | R13: =J13-P13 -> 136402.06 | S13: =R13*0.25 -> 34100.514 | T13: =R13-S13 -> 102301.54 | U13: =T13/H13 -> 0.11602444
A14: 2027 | B14: Jul | C14: =C13*D14 -> 0.019945176 | D14: 1.12 | E14: =E13*D14 -> 1361.2583 | F14: =F13+E14 -> 9861.3768 | G14: =E14/5 -> 272.25165 | H14: =G14*Valores!$D$7 -> 987531 | I14: =G14*Valores!$D$9 -> 612566.22 | J14: =H14-I14 -> 374964.78 | K14: =H14*'P&L'!$B$22 -> 49376.55 | L14: =H14*'P&L'!$B$29 -> 19750.62 | M14: =H14*'P&L'!$B$35 -> 24688.275 | N14: =H14*'P&L'!$B$41 -> 79002.48 | O14: =H14*'P&L'!$B$46 -> 49376.55 | P14: =SUM(K14:O14) -> 222194.48 | Q14: =P14/H14 -> 0.225 | R14: =J14-P14 -> 152770.3 | S14: =R14*0.25 -> 38192.576 | T14: =R14-S14 -> 114577.73 | U14: =T14/H14 -> 0.11602444
... A31: 2028 | B31: Dic | C31: =C30*D31 -> 0.068960715 | D31: 1.1 | E31: =E30*D31 -> 4706.5688 | F31: =F30+E31 -> 57280.842 | G31: =E31/5 -> 941.31376 | H31: =G31*Valores!$D$7 -> 3414401.7 | I31: =G31*Valores!$D$9 -> 2117956 | J31: =H31-I31 -> 1296445.8 | K31: =H31*'P&L'!$B$22 -> 170720.09 | L31: =H31*'P&L'!$B$29 -> 68288.034 | M31: =H31*'P&L'!$B$35 -> 85360.043 | N31: =H31*'P&L'!$B$41 -> 273152.14 | O31: =H31*'P&L'!$B$46 -> 170720.09 | P31: =SUM(K31:O31) -> 768240.39 | Q31: =P31/H31 -> 0.225 | R31: =J31-P31 -> 528205.38 | S31: =R31*0.25 -> 132051.34 | T31: =R31-S31 -> 396154.03 | U31: =T31/H31 -> 0.11602444
A32: 2029 | B32: Ene | C32: =C30*D32 -> 0.065199221 | D32: 1.04 | E32: =E31*D32 -> 4894.8315 | F32: =F31+E32 -> 62175.673 | G32: =E32/5 -> 978.96631 | H32: =G32*Valores!$D$7 -> 3550977.8 | I32: =G32*Valores!$D$9 -> 2202674.2 | J32: =H32-I32 -> 1348303.6 | K32: =H32*'P&L'!$B$22 -> 177548.89 | L32: =H32*'P&L'!$B$29 -> 71019.556 | M32: =H32*'P&L'!$B$35 -> 88774.445 | N32: =H32*'P&L'!$B$41 -> 284078.22 | O32: =H32*'P&L'!$B$46 -> 177548.89 | P32: =SUM(K32:O32) -> 798970 | Q32: =P32/H32 -> 0.225 | R32: =J32-P32 -> 549333.59 | S32: =R32*0.25 -> 137333.4 | T32: =R32-S32 -> 412000.19 | U32: =T32/H32 -> 0.11602444
A33: 2029 | B33: Feb | C33: =C31*D33 -> 0.071719143 | D33: 1.04 | E33: =E32*D33 -> 5090.6248 | F33: =F32+E33 -> 67266.298 | G33: =E33/5 -> 1018.125 | H33: =G33*Valores!$D$7 -> 3693016.9 | I33: =G33*Valores!$D$9 -> 2290781.2 | J33: =H33-I33 -> 1402235.7 | K33: =H33*'P&L'!$B$22 -> 184650.84 | L33: =H33*'P&L'!$B$29 -> 73860.338 | M33: =H33*'P&L'!$B$35 -> 92325.422 | N33: =H33*'P&L'!$B$41 -> 295441.35 | O33: =H33*'P&L'!$B$46 -> 184650.84 | P33: =SUM(K33:O33) -> 830928.8 | Q33: =P33/H33 -> 0.225 | R33: =J33-P33 -> 571306.94 | S33: =R33*0.25 -> 142826.73 | T33: =R33-S33 -> 428480.2 | U33: =T33/H33 -> 0.11602444
A34: 2029 | B34: Mar | C34: =C33*D34 -> 0.074587909 | D34: 1.04 | E34: =E33*D34 -> 5294.2498 | F34: =F33+E34 -> 72560.548 | G34: =E34/5 -> 1058.85 | H34: =G34*Valores!$D$7 -> 3840737.6 | I34: =G34*Valores!$D$9 -> 2382412.4 | J34: =H34-I34 -> 1458325.2 | K34: =H34*'P&L'!$B$22 -> 192036.88 | L34: =H34*'P&L'!$B$29 -> 76814.751 | M34: =H34*'P&L'!$B$35 -> 96018.439 | N34: =H34*'P&L'!$B$41 -> 307259.01 | O34: =H34*'P&L'!$B$46 -> 192036.88 | P34: =SUM(K34:O34) -> 864165.95 | Q34: =P34/H34 -> 0.225 | R34: =J34-P34 -> 594159.21 | S34: =R34*0.25 -> 148539.8 | T34: =R34-S34 -> 445619.41 | U34: =T34/H34 -> 0.11602444
A35: 2029 | B35: Abr | C35: =C34*D35 -> 0.078317304 | D35: 1.05 | E35: =E34*D35 -> 5558.9623 | F35: =F34+E35 -> 78119.51 | G35: =E35/5 -> 1111.7925 | H35: =G35*Valores!$D$7 -> 4032774.4 | I35: =G35*Valores!$D$9 -> 2501533 | J35: =H35-I35 -> 1531241.4 | K35: =H35*'P&L'!$B$22 -> 201638.72 | L35: =H35*'P&L'!$B$29 -> 80655.489 | M35: =H35*'P&L'!$B$35 -> 100819.36 | N35: =H35*'P&L'!$B$41 -> 322621.96 | O35: =H35*'P&L'!$B$46 -> 201638.72 | P35: =SUM(K35:O35) -> 907374.25 | Q35: =P35/H35 -> 0.225 | R35: =J35-P35 -> 623867.17 | S35: =R35*0.25 -> 155966.79 | T35: =R35-S35 -> 467900.38 | U35: =T35/H35 -> 0.11602444
A36: 2029 | B36: May | C36: =C35*D36 -> 0.084191102 | D36: 1.075 | E36: =E35*D36 -> 5975.8844 | F36: =F35+E36 -> 84095.394 | G36: =E36/5 -> 1195.1769 | H36: =G36*Valores!$D$7 -> 4335232.5 | I36: =G36*Valores!$D$9 -> 2689148 | J36: =H36-I36 -> 1646084.5 | K36: =H36*'P&L'!$B$22 -> 216761.63 | L36: =H36*'P&L'!$B$29 -> 86704.651 | M36: =H36*'P&L'!$B$35 -> 108380.81 | N36: =H36*'P&L'!$B$41 -> 346818.6 | O36: =H36*'P&L'!$B$46 -> 216761.63 | P36: =SUM(K36:O36) -> 975427.32 | Q36: =P36/H36 -> 0.225 | R36: =J36-P36 -> 670657.21 | S36: =R36*0.25 -> 167664.3 | T36: =R36-S36 -> 502992.91 | U36: =T36/H36 -> 0.11602444
A37: 2029 | B37: Jun | C37: =C36*D37 -> 0.091768302 | D37: 1.09 | E37: =E36*D37 -> 6513.714 | F37: =F36+E37 -> 90609.108 | G37: =E37/5 -> 1302.7428 | H37: =G37*Valores!$D$7 -> 4725403.5 | I37: =G37*Valores!$D$9 -> 2931171.3 | J37: =H37-I37 -> 1794232.1 | K37: =H37*'P&L'!$B$22 -> 236270.17 | L37: =H37*'P&L'!$B$29 -> 94508.069 | M37: =H37*'P&L'!$B$35 -> 118135.09 | N37: =H37*'P&L'!$B$41 -> 378032.28 | O37: =H37*'P&L'!$B$46 -> 236270.17 | P37: =SUM(K37:O37) -> 1063215.8 | Q37: =P37/H37 -> 0.225 | R37: =J37-P37 -> 731016.36 | S37: =R37*0.25 -> 182754.09 | T37: =R37-S37 -> 548262.27 | U37: =T37/H37 -> 0.11602444
A38: 2029 | B38: Jul | C38: =C37*D38 -> 0.10002745 | D38: 1.09 | E38: =E37*D38 -> 7099.9483 | F38: =F37+E38 -> 97709.057 | G38: =E38/5 -> 1419.9897 | H38: =G38*Valores!$D$7 -> 5150689.8 | I38: =G38*Valores!$D$9 -> 3194976.7 | J38: =H38-I38 -> 1955713 | K38: =H38*'P&L'!$B$22 -> 257534.49 | L38: =H38*'P&L'!$B$29 -> 103013.8 | M38: =H38*'P&L'!$B$35 -> 128767.24 | N38: =H38*'P&L'!$B$41 -> 412055.18 | O38: =H38*'P&L'!$B$46 -> 257534.49 | P38: =SUM(K38:O38) -> 1158905.2 | Q38: =P38/H38 -> 0.225 | R38: =J38-P38 -> 796807.83 | S38: =R38*0.25 -> 199201.96 | T38: =R38-S38 -> 597605.88 | U38: =T38/H38 -> 0.11602444

Sheet Directorio
A1: Vista resumida para Directorio
C2: 2026 | E2: 2027 | I2: 2028 | M2: 2029
A3: Concepto | B3: % Venta | C3: Q3 | D3: Q4 | E3: Q1 | F3: Q2 | G3: Q3 | H3: Q4 | I3: Q1 | J3: Q2 | K3: Q3 | L3: Q4 | M3: Q1 | N3: Q2
A4: Ventas Netas | C4: =SUM(Objetivo!$H2:$H4) -> 686914.77 | D4: =SUM(Objetivo!H5:H7) -> 1242610.1 | E4: =SUM(Objetivo!H8:H10) -> 1838721.8 | F4: =SUM(Objetivo!H11:H13) -> 2398202.9 | G4: =SUM(Objetivo!H14:H16) -> 3143903.7 | H4: =SUM(Objetivo!H17:H19) -> 3906044.7 | I4: =SUM(Objetivo!H20:H22) -> 4910213.5 | J4: =SUM(Objetivo!H23:H25) -> 6208736.1 | K4: =SUM(Objetivo!H26:H28) -> 7826820.5 | L4: =SUM(Objetivo!H29:H31) -> 9392478.8 | M4: =SUM(Objetivo!H32:H34) -> 11084732 | N4: =SUM(Objetivo!H35:H37) -> 13093410
A5: Costo Mercadería Vendida | C5: =SUM(Objetivo!I2:I4) -> 426093.75 | D5: =SUM(Objetivo!I5:I7) -> 770791.99 | E5: =SUM(Objetivo!I8:I10) -> 1140560.5 | F5: =SUM(Objetivo!I11:I13) -> 1487607.1 | G5: =SUM(Objetivo!I14:I16) -> 1950165.8 | H5: =SUM(Objetivo!I17:I19) -> 2422922.5 | I5: =SUM(Objetivo!I20:I22) -> 3045809.1 | J5: =SUM(Objetivo!I23:I25) -> 3851283.7 | K5: =SUM(Objetivo!I26:I28) -> 4854982.6 | L5: =SUM(Objetivo!I29:I31) -> 5826161.7 | M5: =SUM(Objetivo!I32:I34) -> 6875867.7 | N5: =SUM(Objetivo!I35:I37) -> 8121852.3
A6: Margen Bruto | C6: =C4-C5 -> 260821.02 | D6: =D4-D5 -> 471818.13 | E6: =E4-E5 -> 698161.28 | F6: =F4-F5 -> 910595.85 | G6: =G4-G5 -> 1193737.9 | H6: =H4-H5 -> 1483122.2 | I6: =I4-I5 -> 1864404.4 | J6: =J4-J5 -> 2357452.4 | ... N6: =N4-N5 -> 4971558.1
A7: Logística | B7: 0.05 | C7: =C$4*$B$7 -> 34345.739 | D7: =D$4*$B$7 -> 62130.506 | E7: =E$4*$B$7 -> 91936.089 | F7: =F$4*$B$7 -> 119910.15 | G7: =G$4*$B$7 -> 157195.18 | H7: =H$4*$B$7 -> 195302.24 | I7: =I$4*$B$7 -> 245510.67 | J7: =J$4*$B$7 -> 310436.8 | ... N7: =N$4*$B$7 -> 654670.52
A8: Administración | B8: 0.02 | C8: =C$4*$B$8 -> 13738.295 | D8: =D$4*$B$8 -> 24852.202 | E8: =E$4*$B$8 -> 36774.436 | F8: =F$4*$B$8 -> 47964.058 | G8: =G$4*$B$8 -> 62878.074 | H8: =H$4*$B$8 -> 78120.894 | I8: =I$4*$B$8 -> 98204.27 | J8: =J$4*$B$8 -> 124174.72 | ... N8: =N$4*$B$8 -> 261868.21
A9: Marketing | B9: 0.025 | C9: =C$4*$B$9 -> 17172.869 | D9: =D$4*$B$9 -> 31065.253 | E9: =E$4*$B$9 -> 45968.045 | F9: =F$4*$B$9 -> 59955.073 | G9: =G$4*$B$9 -> 78597.592 | H9: =H$4*$B$9 -> 97651.118 | I9: =I$4*$B$9 -> 122755.34 | J9: =J$4*$B$9 -> 155218.4 | ... N9: =N$4*$B$9 -> 327335.26
A10: Comercial | B10: 0.08 | C10: =C$4*$B$10 -> 54953.182 | D10: =D$4*$B$10 -> 99408.81 | E10: =E$4*$B$10 -> 147097.74 | F10: =F$4*$B$10 -> 191856.23 | G10: =G$4*$B$10 -> 251512.3 | H10: =H$4*$B$10 -> 312483.58 | I10: =I$4*$B$10 -> 392817.08 | J10: =J$4*$B$10 -> 496698.89 | ... N10: =N$4*$B$10 -> 1047472.8
A11: Costos Financieros | B11: 0.05 | C11: =C$4*$B$11 -> 34345.739 | D11: =D$4*$B$11 -> 62130.506 | E11: =E$4*$B$11 -> 91936.089 | F11: =F$4*$B$11 -> 119910.15 | G11: =G$4*$B$11 -> 157195.18 | H11: =H$4*$B$11 -> 195302.24 | I11: =I$4*$B$11 -> 245510.67 | J11: =J$4*$B$11 -> 310436.8 | ... N11: =N$4*$B$11 -> 654670.52
A12: Resultado antes de impuestos | C12: =C6-C7-C8-C9-C10-C11 -> 106265.2 | D12: =D6-D7-D8-D9-D10-D11 -> 192230.85 | E12: =E6-E7-E8-E9-E10-E11 -> 284448.88 | F12: =F6-F7-F8-F9-F10-F11 -> 371000.19 | G12: =G6-G7-G8-G9-G10-G11 -> 486359.54 | H12: =H6-H7-H8-H9-H10-H11 -> 604262.18 | I12: =I6-I7-I8-I9-I10-I11 -> 759606.33 | J12: =J6-J7-J8-J9-J10-J11 -> 960486.8 | ... N12: =N6-N7-N8-N9-N10-N11 -> 2025540.8
A13: IRAE | C13: =C12*0.25 -> 26566.3 | D13: =D12*0.25 -> 48057.713 | E13: =E12*0.25 -> 71112.219 | F13: =F12*0.25 -> 92750.047 | G13: =G12*0.25 -> 121589.88 | H13: =H12*0.25 -> 151065.54 | I13: =I12*0.25 -> 189901.58 | J13: =J12*0.25 -> 240121.7 | ... N13: =N12*0.25 -> 506385.19
A14: Resultado Neto | C14: =C12-C13 -> 79698.899 | D14: =D12-D13 -> 144173.14 | E14: =E12-E13 -> 213336.66 | F14: =F12-F13 -> 278250.14 | G14: =G12-G13 -> 364769.65 | H14: =H12-H13 -> 453196.63 | I14: =I12-I13 -> 569704.75 | J14: =J12-J13 -> 720365.1 | ... N14: =N12-N13 -> 1519155.6

Sheet P&L
C5: 2026 | I5: 2027 | U5: 2028 | AG5: 2029
D6: Q3 | G6: Q4 | J6: Q1 | M6: Q2 | P6: Q3 | S6: Q4 | V6: Q1 | Y6: Q2 | AB6: Q3 | AE6: Q4 | AH6: Q1 | AK6: Q2 | AN6: Q3 | AQ6: Q4
A7: Estado de Resultados | C7: Julio | D7: Agosto | E7: Setiembre | F7: Octubre | G7: Noviembre | H7: Diciembre | I7: Enero | J7: Febrero | K7: Marzo | L7: Abril | M7: Mayo | N7: Junio | O7: Julio | P7: Agosto | Q7: Setiembre | R7: Octubre | S7: Noviembre | T7: Diciembre | U7: Enero | V7: Febrero | W7: Marzo | X7: Abril | Y7: Mayo | Z7: Junio | AA7: Julio | AB7: Agosto | AC7: Setiembre | AD7: Octubre | AE7: Noviembre | AF7: Diciembre | AG7: Enero | AH7: Febrero | AI7: Marzo | AJ7: Abril | AK7: Mayo | AL7: Junio | AM7: Julio | AN7: Agosto | AO7: Setiembre | AP7: Octubre | AQ7: Noviembre | AR7: Diciembre
A8: Ventas Netas | B8: 1
A9: Inventario Inicial
A10: + Compras
A11: - Inventario Final
A12: Costo de Mercaderías Vendidas (CMV) | B12: 0.7
A13: Resultado Bruto | B13: 0.3
A15: Logística Operativa
A16: Recepción de mercadería | B16: 0.005
A17: Almacenamiento | B17: 0.01
A18: Picking y packing | B18: 0.015
A19: Movimientos internos | B19: 0.01
A20: Gestión logística | B20: 0.005
A21: Mermas e inventario | B21: 0.005
A22: Total Logística | B22: 0.05
A24: Administración
A25: Facturación electrónica | B25: 0.005
A26: Sistemas | B26: 0.003
A27: Contabilidad y liquidaciones | B27: 0.01
A28: Bancarios administrativos | B28: 0.002
A29: Total Administración | B29: 0.02
A31: Marketing
A32: Publicidad RRSS | B32: 0.01
A33: Promociones y descuentos | B33: 0.005
A34: Fletes promocionales | B34: 0.01
A35: Total Marketing | B35: 0.025
A37: Comercial
A38: Gestión comercial y ventas | B38: 0.05
A39: Administración comercial | B39: 0.01
A40: Atención al cliente | B40: 0.02
A41: Total Comercial | B41: =SUM(B38:B40) -> 0.08
A43: Costos Financieros
A44: Medios de pago | B44: 0.03
A45: Intereses | B45: 0.02
A46: Total Costos Financieros | B46: 0.05
A48: EBITDA | B48: 0.075
A49: Depreciaciones y amortizaciones | B49: 0
A50: EBIT | B50: =B48-B49 -> 0.075
...

Sheet Prod. 
A3: CONSEIL OLÉICOLE INTERNATIONAL (NOV 2025)
A4: INTERNATIONAL OLIVE COUNCIL (NOV 2025)
A6: HUILES D'OLIVE - OLIVE OILS
A9: Tableau 1: PRODUCTION (1.000 tm) - Table 1: PRODUCTION (1,000 tonnes)
C12: 1990/91 | D12: 1991/92 | E12: 1992/93 | F12: 1993/94 | G12: 1994/95 | H12: 1995/96 | I12: 1996/97 | J12: 1997/98 | K12: 1998/9 | L12: 1999/0 | M12: 2000/1 | N12: 2001/2 | O12: 2002/3 | P12: 2003/4 | Q12: 2004/5 | R12: 2005/6 | S12: 2006/7 | T12: 2007/8 | U12: 2008/9 | V12: 2009/10 | W12: 2010/11 | X12: 2011/12 | Y12: 2012/13 | Z12: 2013/14 | AA12: 2014/15 | AB12: 2015/16 | AC12: 2016/17 | AD12: 2017/18 | AE12: 2018/19 | AF12: 2019/20 | AG12: 2020/21 | AH12: 2021/22 | AI12: 2022/23 | AJ12: 2023/24 | AK12: 2024/25 | AL12: 2025/26
AK13: (prov.) | AL13: (prev.)
C14: (1) | D14: (2) | E14: (3) | F14: (4) | G14: (5) | H14: (6) | I14: (7) | J14: (8) | K14: (9) | L14: (10) | M14: (11) | N14: (12) | O14: (13) | P14: (14) | Q14: (15) | R14: (16) | S14: (17) | T14: (18) | U14: (19) | V14: (20) | W14: (21) | X14: (22) | Y14: (23) | Z14: (24) | AA14: (25) | AB14: (26) | AC14: (27) | AD14: (28) | AE14: (29) | AF14: (30) | AG14: (31) | AH14: (32) | AI14: (33) | AJ14: (34) | AK14: (35) | AL14: (36)
A15: Chypre | B15: Cyprus | P15: 7 | Q15: 7.5 | R15: 7.2 | S15: 8.3 | T15: 4 | U15: 2.8 | V15: 4.2 | W15: 6.5 | X15: 6.5 | Y15: 5.6 | Z15: 3.8 | AA15: 6.2 | AB15: 6 | AC15: 6 | AD15: 6 | AE15: 6 | AF15: 6 | AG15: 6 | AH15: 6 | AI15: 6 | AJ15: 6 | AK15: 6 | AL15: 6
A16: Croatie | B16: Croatia | Z16: 4.6 | AA16: 1.1 | AB16: 5.5 | AC16: 5 | AD16: 5.1 | AE16: 5.1 | AF16: 5.1 | AG16: 5.1 | AH16: 5.1 | AI16: 5.1 | AJ16: 5.1 | AK16: 5.1 | AL16: 5.1
A17: Espagne | B17: Spain | C17: 639.4 | D17: 593 | E17: 623.1 | F17: 550.9 | G17: 538.8 | H17: 337.6 | I17: 947.3 | J17: 1077 | K17: 791.9 | L17: 669.1 | M17: 973.7 | N17: 1411.4 | O17: 861.1 | P17: 1412 | Q17: 989.8 | R17: 826.9 | S17: 1111.4 | T17: 1236.1 | U17: 1030 | V17: 1401.5 | W17: 1391.9 | X17: 1615 | Y17: 618.2 | Z17: 1781.5 | AA17: 842.2 | AB17: 1403.3 | AC17: 1290.6 | AD17: 1250 | AE17: 1250 | AF17: 1250 | AG17: 1250 | AH17: 1250 | AI17: 1250 | AJ17: 1250 | AK17: 1250 | AL17: 1250
A18: France | B18: France | C18: 1 | D18: 4.3 | E18: 1.6 | F18: 2.3 | G18: 2 | H18: 2.3 | I18: 2.5 | J18: 2.7 | K18: 3.4 | L18: 4.1 | M18: 3.2 | N18: 3.6 | O18: 4.7 | P18: 4.6 | Q18: 4.7 | R18: 4.4 | S18: 3.3 | T18: 4.7 | U18: 7 | V18: 5.7 | W18: 6.1 | X18: 3.2 | Y18: 5.1 | Z18: 4.8 | AA18: 1.7 | AB18: 5.4 | AC18: 2.8 | AD18: 4.5 | AE18: 4.5 | AF18: 4.5 | AG18: 4.5 | AH18: 4.5 | AI18: 4.5 | AJ18: 4.5 | AK18: 4.5 | AL18: 4.5
A19: Grèce | B19: Greece | C19: 170 | D19: 385 | E19: 310 | F19: 254 | G19: 350 | H19: 400 | I19: 390 | J19: 375 | K19: 473 | L19: 420 | M19: 430 | N19: 358.3 | O19: 414 | P19: 308 | Q19: 435 | R19: 424 | S19: 370 | T19: 327.2 | U19: 305 | V19: 320 | W19: 301 | X19: 294.6 | Y19: 357.9 | Z19: 132 | AA19: 300 | AB19: 320 | AC19: 195 | AD19: 320 | AE19: 320 | AF19: 320 | AG19: 320 | AH19: 320 | AI19: 320 | AJ19: 320 | AK19: 320 | AL19: 320
A20: Italie | B20: Italy | C20: 163.3 | D20: 674.5 | E20: 435 | F20: 520 | G20: 448 | H20: 620 | I20: 370 | J20: 620 | K20: 403.5 | L20: 735 | M20: 509 | N20: 656.7 | O20: 634 | P20: 685 | Q20: 879 | R20: 636.5 | S20: 490 | T20: 510 | U20: 540 | V20: 430 | W20: 440 | X20: 399.2 | Y20: 415.5 | Z20: 463.7 | AA20: 222 | AB20: 474.6 | AC20: 182.3 | AD20: 432 | AE20: 432 | AF20: 432 | AG20: 432 | AH20: 432 | AI20: 432 | AJ20: 432 | AK20: 432 | AL20: 432
A21: Malte | B21: Malta | Z21: 0.04 | AA21: 0.1 | AB21: 0.04 | AC21: 0.04 | AD21: 0.04 | AE21: 0.04 | AF21: 0.04 | AG21: 0.04 | AH21: 0.04 | AI21: 0.04 | AJ21: 0.04 | AK21: 0.04 | AL21: 0.04
A22: Portugal | B22: Portugal | C22: 20 | D22: 62 | E22: 22 | F22: 32.1 | G22: 32.2 | H22: 43.7 | I22: 44.8 | J22: 42 | K22: 35.1 | L22: 50.2 | M22: 24.6 | N22: 33.7 | O22: 28.9 | P22: 31.2 | Q22: 41.2 | R22: 29.1 | S22: 47.5 | T22: 36.3 | U22: 53.4 | V22: 62.5 | W22: 62.9 | X22: 76.2 | Y22: 59.2 | Z22: 91.6 | AA22: 61 | AB22: 109.1 | AC22: 69.4 | AD22: 125 | AE22: 125 | AF22: 125 | AG22: 125 | AH22: 125 | AI22: 125 | AJ22: 125 | AK22: 125 | AL22: 125
A23: Slovénie | B23: Slovenia | P23: 0.2 | Q23: 0 | R23: 0.5 | S23: 0.3 | T23: 0.4 | U23: 0.5 | V23: 0.7 | W23: 0.7 | X23: 0.5 | Y23: 0.2 | Z23: 0.6 | AA23: 0.2 | AB23: 0.5 | AC23: 0.4 | AD23: 0.4 | AE23: 0.4 | AF23: 0.4 | AG23: 0.4 | AH23: 0.4 | AI23: 0.4 | AJ23: 0.4 | AK23: 0.4 | AL23: 0.4
A25: Albanie | B25: Albania | T25: 4 | U25: 6 | V25: 5 | W25: 8 | X25: 7 | Y25: 12 | Z25: 10.5 | AA25: 11 | AB25: 10 | AC25: 11.5 | AD25: 11 | AE25: 12.5 | AF25: 11.5 | AG25: 13 | AH25: 16.5 | AI25: 29 | AJ25: 28.5 | AK25: 25 | AL25: 25.5
A26: Algérie | B26: Algeria | C26: 6 | D26: 37 | E26: 27 | F26: 21 | G26: 16.5 | H26: 51.5 | I26: 50.5 | J26: 15 | K26: 54.5 | L26: 33.5 | M26: 26.5 | N26: 25.5 | O26: 15 | P26: 69.5 | Q26: 33.5 | R26: 32 | S26: 21.5 | T26: 24 | U26: 61.5 | V26: 26.5 | W26: 67 | X26: 39.5 | Y26: 66 | Z26: 44 | AA26: 69.5 | AB26: 82 | AC26: 63 | AD26: 82.5 | AE26: 97 | AF26: 126 | AG26: 70.5 | AH26: 94.5 | AI26: 75.5 | AJ26: 64 | AK26: 85 | AL26: 75.5
A27: A. Saoudite | B27: Saudi Arabia | AH27: 5 | AI27: 29.5 | AJ27: 32 | AK27: 30 | AL27: 34
A28: Argentine | B28: Argentina | C28: 8 | D28: 9 | E28: 10 | F28: 8 | G28: 6.5 | H28: 11 | I28: 11.5 | J28: 8 | K28: 6.5 | L28: 11 | M28: 4 | N28: 10 | O28: 11 | P28: 13.5 | Q28: 18 | R28: 23 | S28: 15 | T28: 27 | U28: 23 | V28: 17 | W28: 20 | X28: 32 | Y28: 17 | Z28: 30 | AA28: 30 | AB28: 24 | AC28: 24 | AD28: 45 | AE28: 28 | AF28: 30 | AG28: 30 | AH28: 33 | AI28: 32 | AJ28: 43 | AK28: 33 | AL28: 23
A29: Azerbaijan | B29: Azerbaïdjan | AI29: 2 | AJ29: 1 | AK29: 2 | AL29: 1.5
A30: Bosnia and Herzegovine | B30: Bosnie-Herzégovine | AI30: 0 | AJ30: 0 | AK30: 0 | AL30: 0
A31: Chypre | B31: Cyprus | C31: 2 | D31: 1.5 | E31: 3 | F31: 3 | G31: 3 | H31: 2.5 | I31: 2 | J31: 1.5 | K31: 2.5 | L31: 3.5 | M31: 5.5 | N31: 6.5 | O31: 7
A32: Croatie | B32: Croatia | J32: 1.5 | K32: 5 | L32: 9 | M32: 5.5 | N32: 5 | O32: 7 | P32: 3 | Q32: 5 | R32: 5 | S32: 4 | T32: 4.5 | U32: 6 | V32: 5 | W32: 5 | X32: 4 | Y32: 4
A33: Egypte | B33: Egypt | C33: 0.5 | D33: 1 | E33: 1 | F33: 1 | G33: 1 | H33: 2.5 | I33: 0.5 | J33: 1 | K33: 0.5 | L33: 2.5 | M33: 0.5 | N33: 1.5 | O33: 5 | P33: 2 | Q33: 2.5 | R33: 2.5 | S33: 10.5 | T33: 7.5 | U33: 5 | V33: 3 | W33: 4 | X33: 9 | Y33: 16.5 | Z33: 20 | AA33: 17 | AB33: 16.5 | AC33: 30 | AD33: 39.5 | AE33: 41 | AF33: 40 | AG33: 38 | AH33: 48.5 | AI33: 49.5 | AJ33: 52 | AK33: 45 | AL33: 50
A34: Géorgie | B34: Georgia | AI34: 0 | AJ34: 0 | AK34: 0 | AL34: 0
A35: Iran | B35: Iran | C35: 0.5 | D35: 0.5 | E35: 2 | F35: 3 | G35: 1.5 | H35: 3 | I35: 1.5 | J35: 3 | K35: 2.5 | L35: 2.5 | M35: 3 | N35: 2.5 | O35: 1.5 | P35: 2.5 | Q35: 4 | R35: 4.5 | S35: 4 | T35: 4.5 | U35: 4.5 | V35: 4 | W35: 4 | X35: 7 | Y35: 3.5 | Z35: 5 | AA35: 4.5 | AB35: 5 | AC35: 3.5 | AD35: 7 | AE35: 11.5 | AF35: 9 | AG35: 7.5 | AH35: 13.5 | AI35: 15 | AJ35: 10.5 | AK35: 10 | AL35: 11.5
A36: Irak | B36: Iraq | AI36: 0 | AJ36: 0 | AK36: 0 | AL36: 0
A37: Israël | B37: Israel | C37: 8 | D37: 2.5 | E37: 7.5 | F37: 1.5 | G37: 5.5 | H37: 5 | I37: 5.5 | J37: 3 | K37: 4.5 | L37: 2.5 | M37: 7 | N37: 3.5 | O37: 9 | P37: 3 | Q37: 9 | R37: 3 | S37: 8.5 | T37: 4 | U37: 9 | V37: 3.5 | W37: 12.5 | X37: 13 | Y37: 18 | Z37: 15 | AA37: 18.5 | AB37: 18 | AC37: 18 | AD37: 17 | AE37: 14 | AF37: 19 | AG37: 12 | AH37: 12 | AI37: 45 | AJ37: 11 | AK37: 17 | AL37: 23
A38: Jordanie | B38: Jordan | C38: 8 | D38: 5 | E38: 14 | F38: 12.5 | G38: 13.5 | H38: 14 | I38: 23 | J38: 14 | K38: 21.5 | L38: 6.5 | M38: 27 | N38: 14 | O38: 28 | P38: 25 | Q38: 29 | R38: 22 | S38: 37 | T38: 21.5 | U38: 18.5 | V38: 17 | W38: 27 | X38: 19.5 | Y38: 21.5 | Z38: 19 | AA38: 23 | AB38: 29.5 | AC38: 20 | AD38: 21 | AE38: 21 | AF38: 34.5 | AG38: 24.5 | AH38: 23.5 | AI38: 25.5 | AJ38: 25 | AK38: 36 | AL38: 23.5
A39: Liban | B39: Lebanon | C39: 6 | D39: 5 | E39: 8 | F39: 2 | G39: 5 | H39: 5 | I39: 6.5 | J39: 3.5 | K39: 7 | L39: 5 | M39: 6 | N39: 5 | O39: 6 | P39: 7.5 | Q39: 6 | R39: 5.5 | S39: 6 | T39: 10.5 | U39: 12 | V39: 9 | W39: 32 | X39: 14 | Y39: 14 | Z39: 16.5 | AA39: 21 | AB39: 23 | AC39: 25 | AD39: 17 | AE39: 17.5 | AF39: 14 | AG39: 14 | AH39: 18 | AI39: 30 | AJ39: 16 | AK39: 19 | AL39: 19.5
A40: Libye | B40: Libya | C40: 7 | D40: 10 | E40: 6 | F40: 8 | G40: 6.5 | H40: 4 | I40: 10 | J40: 6 | K40: 8 | L40: 7 | M40: 4 | N40: 7 | O40: 6.5 | P40: 12.5 | Q40: 12.5 | R40: 9 | S40: 11 | T40: 13 | U40: 15 | V40: 15 | W40: 15 | X40: 15 | Y40: 15 | Z40: 18 | AA40: 15.5 | AB40: 18 | AC40: 16 | AD40: 18 | AE40: 16 | AF40: 17 | AG40: 16.5 | AH40: 17 | AI40: 15.5 | AJ40: 15.5 | AK40: 16 | AL40: 16
A41: Maroc | B41: Morocco | C41: 36 | D41: 50 | E41: 38 | F41: 40 | G41: 45 | H41: 35 | I41: 110 | J41: 70 | K41: 65 | L41: 40 | M41: 35 | N41: 60 | O41: 45 | P41: 100 | Q41: 50 | R41: 75 | S41: 75 | T41: 85 | U41: 85 | V41: 140 | W41: 130 | X41: 120 | Y41: 100 | Z41: 130 | AA41: 120 | AB41: 130 | AC41: 110 | AD41: 140 | AE41: 200 | AF41: 145 | AG41: 160 | AH41: 190 | AI41: 107 | AJ41: 106 | AK41: 90 | AL41: 160
A42: Montenegro | B42: Montenegro | C42: 3.5 | D42: 2 | E42: 1.5 | F42: 2 | G42: 2.5 | H42: 1.5 | I42: 0.5 | J42: 0.5 | K42: 1 | L42: 1 | M42: 0.5 | N42: 0.5 | O42: 0.5 | P42: 0.5 | Q42: 0.5 | R42: 0.5 | S42: 0.5 | T42: 0.5 | U42: 0.5 | V42: 0.5 | W42: 0.5 | X42: 0.5 | Y42: 0.5 | Z42: 0.5 | AA42: 0.5 | AB42: 0.5 | AC42: 0.5 | AD42: 0.5 | AE42: 0.5 | AF42: 0.5 | AG42: 0.5 | AH42: 0.5 | AI42: 0.5 | AJ42: 0.5 | AK42: 0.5 | AL42: 0.5
A43: Ouzbékistan | B43: Uzbekistan | AH43: 0 | AI43: 0 | AJ43: 0 | AK43: 0 | AL43: 0
A44: Palestine | B44: Palestine | E44: 31 | F44: 1 | G44: 8 | H44: 12 | I44: 12 | J44: 9 | K44: 5.5 | L44: 2 | M44: 20 | N44: 18 | O44: 21.5 | P44: 5 | Q44: 20 | R44: 10 | S44: 31.5 | T44: 8 | U44: 20 | V44: 5.5 | W44: 25 | X44: 15.5 | Y44: 15.5 | Z44: 17.5 | AA44: 24.5 | AB44: 21 | AC44: 20 | AD44: 19.5 | AE44: 15 | AF44: 39.5 | AG44: 14.5 | AH44: 14.5 | AI44: 36 | AJ44: 10.5 | AK44: 27.5 | AL44: 7
A45: Tunisie | B45: Tunisia | C45: 175 | D45: 250 | E45: 120 | F45: 235 | G45: 100 | H45: 60 | I45: 270 | J45: 93 | K45: 215 | L45: 210 | M45: 130 | N45: 35 | O45: 72 | P45: 280 | Q45: 130 | R45: 220 | S45: 160 | T45: 170 | U45: 160 | V45: 150 | W45: 120 | X45: 182 | Y45: 220 | Z45: 70 | AA45: 340 | AB45: 140 | AC45: 100 | AD45: 325 | AE45: 140 | AF45: 440 | AG45: 140 | AH45: 240 | AI45: 217 | AJ45: 220 | AK45: 340 | AL45: 450
A46: Turquie | B46: Türkiye | C46: 80 | D46: 60 | E46: 56 | F46: 48 | G46: 160 | H46: 40 | I46: 200 | J46: 40 | K46: 170 | L46: 70 | M46: 175 | N46: 65 | O46: 140 | P46: 79 | Q46: 145 | R46: 112 | S46: 165 | T46: 72 | U46: 130 | V46: 147 | W46: 160 | X46: 191 | Y46: 195 | Z46: 135 | AA46: 160 | AB46: 150 | AC46: 178 | AD46: 263 | AE46: 193.5 | AF46: 230 | AG46: 193.5 | AH46: 235 | AI46: 451 | AJ46: 215 | AK46: 505 | AL46: 290
A47: UE | B47: EU | C47: 994 | D47: 1719 | E47: 1391.5 | F47: 1359.5 | G47: 1371 | H47: 1403.5 | I47: 1754.5 | J47: 2116.5 | K47: 1707 | L47: 1878.5 | M47: 1940.5 | N47: 2463.5 | O47: 1942.5 | P47: 2448 | Q47: 2357 | R47: 1928.5 | S47: 2031 | T47: 2118.5 | U47: 1939 | V47: 2224.5 | W47: 2209 | X47: 2395 | Y47: 1461.5 | Z47: 2482.5 | AA47: 1434.5 | AB47: 2324 | AC47: 1752 | AD47: 2188.5 | AE47: 2263.5 | AF47: 1920 | AG47: 2051 | AH47: 2271.5 | AI47: 1392 | AJ47: 1549 | AK47: 2110 | AL47: 2056
A48: Uruguay | B48: Uruguay | Z48: 0.5 | AA48: 0.5 | AB48: 0.5 | AC48: 0.5 | AD48: 1 | AE48: 0.5 | AF48: 2.5 | AG48: 0.5 | AH48: 1.5 | AI48: 1.5 | AJ48: 2 | AK48: 0.5 | AL48: 0.5
...

Sheet Imp.
A3: CONSEIL OLÉICOLE INTERNATIONAL (NOV 2025)
A4: INTERNATIONAL OLIVE COUNCIL (NOV 2025)
A6: HUILES D'OLIVE - OLIVE OILS
A9: Tableau 2: IMPORTATIONS (1.000 tm) - Table 2: IMPORTS (1,000 tonnes)
C12: 1990/91 | D12: 1991/92 | E12: 1992/93 | F12: 1993/94 | G12: 1994/95 | H12: 1995/96 | I12: 1996/97 | J12: 1997/98 | K12: 1998/9 | L12: 1999/0 | M12: 2000/1 | N12: 2001/2 | O12: 2002/3 | P12: 2003/4 | Q12: 2004/5 | R12: 2005/6 | S12: 2006/7 | T12: 2007/8 | U12: 2008/9 | V12: 2009/10 | W12: 2010/11 | X12: 2011/12 | Y12: 2012/13 | Z12: 2013/14 | AA12: 2014/15 | AB12: 2015/16 | AC12: 2016/17 | AD12: 2017/18 | AE12: 2018/19 | AF12: 2019/20 | AG12: 2020/21 | AH12: 2021/22 | AI12: 2022/23 | AJ12: 2023/24 | AK12: 2024/25 | AL12: 2025/26
AK13: (prov.) | AL13: (prev.)
C14: (1) | D14: (2) | E14: (3) | F14: (4) | G14: (5) | H14: (6) | I14: (7) | J14: (8) | K14: (9) | L14: (10) | M14: (11) | N14: (12) | O14: (13) | P14: (14) | Q14: (15) | R14: (16) | S14: (17) | T14: (18) | U14: (19) | V14: (20) | W14: (21) | X14: (22) | Y14: (23) | Z14: (24) | AA14: (25) | AB14: (26) | AC14: (27) | AD14: (28) | AE14: (29) | AF14: (30) | AG14: (31) | AH14: (32) | AI14: (33) | AJ14: (34) | AK14: (35) | AL14: (36)
A16: Albanie | B16: Albania | T16: 0.5 | U16: 1 | V16: 1 | W16: 1 | X16: 1 | Y16: 1 | Z16: 1 | AA16: 1.5 | AB16: 1.5 | AC16: 1.5 | AD16: 1.5 | AE16: 1 | AF16: 1.5 | AG16: 1.5 | AH16: 1.5 | AI16: 1 | AJ16: 1 | AK16: 1 | AL16: 1
A17: Algérie | B17: Algeria | C17: 0 | D17: 0 | E17: 0 | F17: 0 | G17: 0 | H17: 0 | I17: 0 | J17: 0 | K17: 0 | L17: 1 | M17: 0 | N17: 1 | O17: 0 | P17: 0 | Q17: 0 | R17: 0 | S17: 0 | T17: 0.5 | U17: 0.5 | V17: 0 | W17: 0 | X17: 0 | Y17: 0 | Z17: 0 | AA17: 0.5 | AB17: 0.5 | AC17: 0 | AD17: 0 | AE17: 0 | AF17: 0 | AG17: 0 | AH17: 0 | AI17: 0 | AJ17: 0 | AK17: 0 | AL17: 0
A18: A. Saoudite | B18: Saudi Arabia | AH18: 35.5 | AI18: 37 | AJ18: 21.5 | AK18: 5 | AL18: 6
A19: Argentine | B19: Argentina | C19: 0 | D19: 0 | E19: 0 | F19: 0 | G19: 0.5 | H19: 0.5 | I19: 6.5 | J19: 7 | K19: 3.5 | L19: 2 | M19: 5.5 | N19: 0.5 | O19: 0 | P19: 0 | Q19: 0 | R19: 0.5 | S19: 0 | T19: 0 | U19: 0 | V19: 0 | W19: 0 | X19: 0 | Y19: 0 | Z19: 0 | AA19: 0 | AB19: 0 | AC19: 0 | AD19: 0 | AE19: 1.5 | AF19: 0.5 | AG19: 1 | AH19: 1.5 | AI19: 3.5 | AJ19: 0 | AK19: 0.5 | AL19: 3
A20: Azerbaijan | B20: Azerbaïdjan (Q) | AI20: 0.5 | AJ20: 0.5 | AK20: 0.5 | AL20: 0.5
A21: Bosnia and Herzegovine | B21: Bosnie-Herzégovine | AI21: 0.5 | AJ21: 0.5 | AK21: 0.5 | AL21: 0.5
A22: Chypre | B22: Cyprus | C22: 0 | D22: 0 | E22: 0 | F22: 0 | G22: 0 | H22: 0 | I22: 0 | J22: 0.5 | K22: 0.5 | L22: 0.5 | M22: 0 | N22: 0 | O22: 0
A23: Croatie | B23: Croatia | J23: 0.5 | K23: 0.5 | L23: 1 | M23: 2 | N23: 1.5 | O23: 0.5 | P23: 0.5 | Q23: 0.5 | R23: 0.5 | S23: 1.5 | T23: 1.5 | U23: 1.5 | V23: 1.5 | W23: 2 | X23: 2.5 | Y23: 2.5
A24: Egypte | B24: Egypt | C24: 1 | D24: 0 | E24: 1 | F24: 0.5 | G24: 1 | H24: 0.5 | I24: 0.5 | J24: 0.5 | K24: 0.5 | L24: 0.5 | M24: 0.5 | N24: 0.5 | O24: 0.5 | P24: 0 | Q24: 0 | R24: 0 | S24: 0 | T24: 0 | U24: 3.5 | V24: 4 | W24: 1 | X24: 1.5 | Y24: 1 | Z24: 1 | AA24: 6 | AB24: 0.5 | AC24: 0 | AD24: 2.5 | AE24: 3.5 | AF24: 4.5 | AG24: 4.5 | AH24: 2 | AI24: 0 | AJ24: 0 | AK24: 0 | AL24: 0
A25: Géorgie | B25: Georgia | AE25: 0.5 | AF25: 0.5 | AG25: 0.5 | AH25: 0.5 | AI25: 0.5 | AJ25: 0.5 | AK25: 0.5 | AL25: 0.5
A26: Iran | B26: Iran | C26: 2 | D26: 2 | E26: 0.5 | F26: 0.5 | G26: 1 | H26: 2 | I26: 2 | J26: 1 | K26: 0 | L26: 0 | M26: 0 | N26: 0 | O26: 0 | P26: 1 | Q26: 0.5 | R26: 2 | S26: 1.5 | T26: 3 | U26: 3 | V26: 3 | W26: 3.5 | X26: 4.5 | Y26: 4 | Z26: 5 | AA26: 5.5 | AB26: 5 | AC26: 2.5 | AD26: 3.5 | AE26: 3 | AF26: 3 | AG26: 4 | AH26: 4 | AI26: 2 | AJ26: 3.5 | AK26: 4 | AL26: 5.5
A27: Irak | B27: Iraq | T27: 0 | U27: 0 | V27: 8.5 | W27: 6 | X27: 6 | Y27: 6 | Z27: 6 | AA27: 1.5 | AB27: 1.5 | AC27: 1.5 | AD27: 1.5 | AE27: 1.5 | AF27: 1.5 | AG27: 1 | AH27: 1 | AI27: 1.5 | AJ27: 1.5 | AK27: 2 | AL27: 2
A28: Israël | B28: Israel | C28: 0 | D28: 1 | E28: 0 | F28: 1 | G28: 1.5 | H28: 3.5 | I28: 2 | J28: 2.5 | K28: 5 | L28: 10 | M28: 7 | N28: 10.5 | O28: 6 | P28: 10.5 | Q28: 7.5 | R28: 13.5 | S28: 8 | T28: 12 | U28: 8 | V28: 13 | W28: 7.5 | X28: 3 | Y28: 3 | Z28: 4.5 | AA28: 2.5 | AB28: 2 | AC28: 3 | AD28: 4 | AE28: 10.5 | AF28: 12.5 | AG28: 10 | AH28: 11 | AI28: 10.5 | AJ28: 9.5 | AK28: 13 | AL28: 12
A29: Jordanie | B29: Jordan | C29: 1 | D29: 8.5 | E29: 4 | F29: 8 | G29: 7 | H29: 0.5 | I29: 0.5 | J29: 2 | K29: 0 | L29: 1.5 | M29: 0.5 | N29: 0 | O29: 0 | P29: 0 | Q29: 0 | R29: 0 | S29: 0 | T29: 0 | U29: 1.5 | V29: 5 | W29: 15 | X29: 0 | Y29: 0 | Z29: 0 | AA29: 0 | AB29: 0 | AC29: 0 | AD29: 0 | AE29: 0 | AF29: 0 | AG29: 0 | AH29: 0 | AI29: 0 | AJ29: 0 | AK29: 0 | AL29: 0
A30: Liban | B30: Lebanon | C30: 1.5 | D30: 3.5 | E30: 0.5 | F30: 2 | G30: 3 | H30: 4 | I30: 3.5 | J30: 4 | K30: 3.5 | L30: 3 | M30: 2 | N30: 2 | O30: 0 | P30: 0 | Q30: 0.5 | R30: 0 | S30: 2 | T30: 1 | U30: 2 | V30: 3 | W30: 0 | X30: 2.5 | Y30: 2.5 | Z30: 4.5 | AA30: 3.5 | AB30: 4.5 | AC30: 3.5 | AD30: 5.5 | AE30: 0 | AF30: 0 | AG30: 0 | AH30: 0 | AI30: 0 | AJ30: 0 | AK30: 0 | AL30: 0
A31: Libye | B31: Libya | C31: 5 | D31: 10 | E31: 1 | F31: 1.5 | G31: 1.5 | H31: 1 | I31: 1 | J31: 1 | K31: 10 | L31: 1 | M31: 3 | N31: 1 | O31: 2 | P31: 2 | Q31: 0 | R31: 0 | S31: 0 | T31: 0 | U31: 0 | V31: 0 | W31: 0 | X31: 0 | Y31: 0 | Z31: 0 | AA31: 0 | AB31: 0 | AC31: 0 | AD31: 0 | AE31: 0 | AF31: 0 | AG31: 0 | AH31: 0 | AI31: 0 | AJ31: 0 | AK31: 0 | AL31: 0
A32: Maroc | B32: Morocco | C32: 0 | D32: 1 | E32: 3 | F32: 2 | G32: 2.5 | H32: 0.5 | I32: 0 | J32: 0 | K32: 0.5 | L32: 4 | M32: 4.5 | N32: 5 | O32: 10.5 | P32: 1.5 | Q32: 1.5 | R32: 1 | S32: 6 | T32: 5 | U32: 15 | V32: 0 | W32: 4 | X32: 0 | Y32: 16 | Z32: 9.5 | AA32: 8 | AB32: 9 | AC32: 7 | AD32: 12 | AE32: 5.5 | AF32: 6.5 | AG32: 7.5 | AH32: 5 | AI32: 12 | AJ32: 4.5 | AK32: 30 | AL32: 8.5
A33: Montenegro | B33: Montenegro | C33: 3 | D33: 0.5 | E33: 0 | F33: 0 | G33: 0 | H33: 0 | I33: 0 | J33: 0 | K33: 0 | L33: 0 | M33: 0 | N33: 0 | O33: 0 | P33: 0 | Q33: 0 | R33: 0 | S33: 0 | T33: 0 | U33: 0 | V33: 0 | W33: 0 | X33: 0 | Y33: 0 | Z33: 0 | AA33: 0 | AB33: 0 | AC33: 0 | AD33: 0 | AE33: 0 | AF33: 0 | AG33: 0 | AH33: 0.5 | AI33: 0 | AJ33: 0 | AK33: 0 | AL33: 0
A34: Ouzbékistan | B34: Uzbekistan | AE34: 0 | AF34: 0.5 | AG34: 0.5 | AH34: 0.5 | AI34: 0.5 | AJ34: 1 | AK34: 0.5 | AL34: 0.5
A35: Palestine | B35: Palestine | E35: 0 | F35: 0 | G35: 0.5 | H35: 0 | I35: 0 | J35: 0 | K35: 0 | L35: 0 | M35: 0 | N35: 0 | O35: 0 | P35: 0 | Q35: 0 | R35: 0 | S35: 0 | T35: 0 | U35: 0 | V35: 0.5 | W35: 0 | X35: 0 | Y35: 0 | Z35: 0 | AA35: 0 | AB35: 0 | AC35: 0 | AD35: 0 | AE35: 0 | AF35: 0 | AG35: 0 | AH35: 0 | AI35: 0 | AJ35: 0 | AK35: 0 | AL35: 0
A36: Tunisie | B36: Tunisia | C36: 0 | D36: 0 | E36: 0 | F36: 0 | G36: 0 | H36: 0 | I36: 0 | J36: 0 | K36: 0 | L36: 0 | M36: 0 | N36: 0 | O36: 0 | P36: 0 | Q36: 0 | R36: 0 | S36: 0 | T36: 0 | U36: 0 | V36: 0 | W36: 0 | X36: 0 | Y36: 0 | Z36: 0 | AA36: 0 | AB36: 0 | AC36: 0 | AD36: 0 | AE36: 0 | AF36: 0 | AG36: 0 | AH36: 0 | AI36: 0 | AJ36: 0 | AK36: 0 | AL36: 0
A37: Turquie | B37: Türkiye | C37: 0 | D37: 0 | E37: 1.5 | F37: 0 | G37: 0 | H37: 0 | I37: 0 | J37: 0 | K37: 1 | L37: 2 | M37: 0 | N37: 0 | O37: 0 | P37: 0 | Q37: 0 | R37: 0 | S37: 0 | T37: 0 | U37: 0 | V37: 0 | W37: 0 | X37: 0 | Y37: 0 | Z37: 0 | AA37: 0 | AB37: 0 | AC37: 0 | AD37: 0 | AE37: 0 | AF37: 0 | AG37: 0 | AH37: 0 | AI37: 0 | AJ37: 0 | AK37: 0 | AL37: 0
A38: UE * | B38: EU * | C38: 125.5 | D38: 135.5 | E38: 101 | F38: 153 | G38: 179 | H38: 73.5 | I38: 145.5 | J38: 118 | K38: 225.5 | L38: 116.5 | M38: 127 | N38: 42.5 | O38: 93.5 | P38: 231.5 | Q38: 186 | R38: 189 | S38: 224 | T38: 162 | U38: 96 | V38: 78 | W38: 82 | X38: 96.5 | Y38: 153 | Z38: 53 | AA38: 224.5 | AB38: 97.5 | AC38: 90.5 | AD38: 180 | AE38: 145 | AF38: 250.5 | AG38: 167.5 | AH38: 151.5 | AI38: 176 | AJ38: 204.5 | AK38: 180 | AL38: 190
A39: Uruguay | B39: Uruguay | Z39: 1 | AA39: 1 | AB39: 1 | AC39: 1 | AD39: 1 | AE39: 1 | AF39: 1 | AG39: 1 | AH39: 1 | AI39: 0.5 | AJ39: 0.5 | AK39: 1 | AL39: 1
A41: TOTAL A | C41: =SUM(C16:C38) -> 139 | D41: =SUM(D16:D38) -> 162 | E41: =SUM(E16:E38) -> 112.5 | F41: =SUM(F16:F38) -> 168.5 | G41: =SUM(G16:G38) -> 197.5 | H41: =SUM(H17:H38) -> 86 | I41: =SUM(I16:I38) -> 161.5 | J41: =SUM(J16:J38) -> 137 | K41: =SUM(K16:K38) -> 250.5 | L41: =SUM(L16:L38) -> 143 | M41: =SUM(M16:M38) -> 152 | N41: =SUM(N16:N38) -> 64.5 | O41: =SUM(O16:O38) -> 113 | P41: =SUM(P16:P38) -> 247 | ... Y41: =SUM(Y16:Y38) -> 189 | Z41: =SUM(Z16:Z39) -> 85.5 | AA41: =SUM(AA16:AA39) -> 254.5 | AB41: =SUM(AB16:AB39) -> 123 | AC41: =SUM(AC16:AC39) -> 110.5 | AD41: =SUM(AD16:AD39) -> 211.5 | AE41: 173 | AF41: 282.5 | AG41: 199 | AH41: 215.5 | AI41: 246 | AJ41: =SUM(AJ16:AJ39) -> 249 | AK41: =SUM(AK16:AK39) -> 238.5 | AL41: =SUM(AL16:AL39) -> 231
A44: A. Saoudite | B44: Saudi Arabia | C44: 6.5 | D44: 7 | E44: 7 | F44: 5 | G44: 5 | H44: 4 | I44: 5 | J44: 5 | K44: 5.5 | L44: 4.5 | M44: 4 | N44: 5 | O44: 7 | P44: 7.5 | Q44: 5.5 | R44: 4.5 | S44: 4 | T44: 5 | U44: 5.5 | V44: 5.5 | W44: 13.5 | X44: 13.5 | Y44: 19.5 | Z44: 20 | AA44: 22 | AB44: 22 | AC44: 23 | AD44: 33.5 | AE44: 34.5 | AF44: 38.5 | AG44: 28
A45: Australie | B45: Australia | C45: 13.5 | D45: 12.5 | E45: 17 | F45: 16 | G45: 19 | H45: 16 | I45: 21.5 | J45: 17.5 | K45: 23.5 | L45: 25 | M45: 30 | N45: 26.5 | O45: 31.5 | P45: 31 | Q45: 28.5 | R45: 29 | S45: 41.5 | T45: 27 | U45: 28.5 | V45: 35 | W45: 32 | X45: 31.5 | Y45: 28.5 | Z45: 28 | AA45: 22 | AB45: 26 | AC45: 29 | AD45: 31 | AE45: 32 | AF45: 36 | AG45: 36 | AH45: 33.5 | AI45: 27.5 | AJ45: 29 | AK45: 42 | AL45: 39.5
A46: Brésil | B46: Brazil | C46: 13.5 | D46: 11 | E46: 17 | F46: 14.5 | G46: 23.5 | H46: 19 | I46: 24.5 | J46: 29 | K46: 23.5 | L46: 25 | M46: 25 | N46: 22.5 | O46: 21 | P46: 23.5 | Q46: 26.5 | R46: 26 | S46: 34.5 | T46: 40 | U46: 42 | V46: 50.5 | W46: 61.5 | X46: 68 | Y46: 73 | Z46: 72.5 | AA46: 66.5 | AB46: 50 | AC46: 59.5 | AD46: 76.5 | AE46: 86 | AF46: 104 | AG46: 106.5 | AH46: 103.5 | AI46: 91 | AJ46: 81 | AK46: 77 | AL46: 78.5
A47: Canada | B47: Canada | C47: 10 | D47: 10 | E47: 13 | F47: 12 | G47: 15 | H47: 14 | I47: 19 | J47: 17.5 | K47: 18.5 | L47: 23 | M47: 25.5 | N47: 24 | O47: 25 | P47: 26 | Q47: 32 | R47: 30 | S47: 32.5 | T47: 29 | U47: 30 | V47: 37 | W47: 40 | X47: 39.5 | Y47: 37 | Z47: 40.5 | AA47: 37.5 | AB47: 41 | AC47: 39.5 | AD47: 47 | AE47: 46.5 | AF47: 57.5 | AG47: 58 | AH47: 53.5 | AI47: 48 | AJ47: 50 | AK47: 73.5 | AL47: 74
A48: Chili | B48: Chile | P48: . | S48: 1 | T48: 0.5 | U48: 1 | V48: 0.5 | W48: 0.5 | X48: 1 | Y48: 0.5 | Z48: 1 | AA48: 0.5 | AB48: 0.5 | AC48: 1 | AD48: 2.5 | AE48: 1.5 | AF48: 1.5 | AG48: 2 | AH48: 3 | AI48: 2.5 | AJ48: 4.5 | AK48: 4.5 | AL48: 4
A49: China | B49: China | U49: 12 | V49: 18 | W49: 29.5 | X49: 40 | Y49: 39 | Z49: 32 | AA49: 31 | AB49: 34 | AC49: 39 | AD49: 38 | AE49: 46 | AF49: 50.5 | AG49: 45.5 | AH49: 49.5 | AI49: 34 | AJ49: 19 | AK49: 32.5 | AL49: 43.5
A50: Etats-Unis | B50: USA | C50: 90 | D50: 87.5 | E50: 108.5 | F50: 111.5 | G50: 121.5 | H50: 105 | I50: 140.5 | J50: 144 | K50: 155 | L50: 175 | M50: 200 | N50: 193 | O50: 191.5 | P50: 226 | Q50: 221 | R50: 232 | S50: 250 | T50: 245 | U50: 255 | V50: 258 | W50: 275 | X50: 300 | Y50: 288 | Z50: 302.5 | AA50: 294.5 | AB50: 314 | AC50: 305 | AD50: 310.5 | AE50: 346.5 | AF50: 391 | AG50: 379.5 | AH50: 399 | AI50: 358.5 | AJ50: 362.5 | AK50: 447 | AL50: 465
A51: Japon | B51: Japan | C51: 4 | D51: 4.5 | E51: 5 | F51: 6.5 | G51: 8.5 | H51: 16.5 | I51: 26 | J51: 34 | K51: 28.5 | L51: 27 | M51: 29 | N51: 31.5 | O51: 30.5 | P51: 32 | Q51: 32 | R51: 30 | S51: 30.5 | T51: 29 | U51: 30 | V51: 40.5 | W51: 35.5 | X51: 43 | Y51: 51 | Z51: 54 | AA51: 59 | AB51: 53.5 | AC51: 54.5 | AD51: 55.5 | AE51: 69 | AF51: 69.5 | AG51: 59 | AH51: 62.5 | AI51: 52 | AJ51: 45.5 | AK51: 34 | AL51: 45
...

Sheet Exp.
A3: CONSEIL OLÉICOLE INTERNATIONAL (NOV 2025)
A4: INTERNATIONAL OLIVE COUNCIL (NOV 2025)
A6: HUILES D'OLIVE - OLIVE OILS
A9: Tableau 3: EXPORTATIONS (1.000 tm) - Cuadro 3: EXPORTS (1,000 tonnes)
C12: 1990/91 | D12: 1991/92 | E12: 1992/93 | F12: 1993/94 | G12: 1994/95 | H12: 1995/96 | I12: 1996/97 | J12: 1997/98 | K12: 1998/9 | L12: 1999/0 | M12: 2000/1 | N12: 2001/2 | O12: 2002/3 | P12: 2003/4 | Q12: 2004/5 | R12: 2005/6 | S12: 2006/7 | T12: 2007/8 | U12: 2008/9 | V12: 2009/10 | W12: 2010/11 | X12: 2011/12 | Y12: 2012/13 | Z12: 2013/14 | AA12: 2014/15 | AB12: 2015/16 | AC12: 2016/17 | AD12: 2017/18 | AE12: 2018/19 | AF12: 2019/20 | AG12: 2020/21 | AH12: 2021/22 | AI12: 2022/23 | AJ12: 2023/24 | AK12: 2024/25 | AL12: 2025/26
AK13: (prov.) | AL13: (prev.)
C14: (1) | D14: (2) | E14: (3) | F14: (4) | G14: (5) | H14: (6) | I14: (7) | J14: (8) | K14: (9) | L14: (10) | M14: (11) | N14: (12) | O14: (13) | P14: (14) | Q14: (15) | R14: (16) | S14: (17) | T14: (18) | U14: (19) | V14: (20) | W14: (21) | X14: (22) | Y14: (23) | Z14: (24) | AA14: (25) | AB14: (26) | AC14: (27) | AD14: (28) | AE14: (29) | AF14: (30) | AG14: (31) | AH14: (32) | AI14: (33) | AJ14: (34) | AK14: (35) | AL14: (36)
A16: Albanie | B16: Albania | T16: 0 | U16: 0 | V16: 0 | W16: 0 | X16: 0 | Y16: 0 | Z16: 0 | AA16: 0 | AB16: 0 | AC16: 0 | AD16: 0 | AE16: 0 | AF16: 0 | AG16: 0 | AH16: 0 | AI16: 6 | AJ16: 3 | AK16: 3 | AL16: 3
A17: Algérie | B17: Algeria | C17: 0 | D17: 0 | E17: 0 | F17: 0 | G17: 0 | H17: 0 | I17: 0 | J17: 0 | K17: 0 | L17: 0 | M17: 0 | N17: 0 | O17: 0 | P17: 0 | Q17: 0 | R17: 0.5 | S17: 0 | T17: 0 | U17: 0 | V17: 0 | W17: 0 | X17: 0 | Y17: 0 | Z17: 0 | AA17: 0 | AB17: 0 | AC17: 0 | AD17: 0 | AE17: 0 | AF17: 0 | AG17: 0.5 | AH17: 0 | AI17: 0 | AJ17: 1 | AK17: 0 | AL17: 0
A18: A. Saoudite | B18: Saudi Arabia | AH18: 0.5 | AI18: 0 | AJ18: 1.5 | AK18: 0 | AL18: 0
A19: Argentine | B19: Argentina | C19: 4 | D19: 5 | E19: 5.5 | F19: 4 | G19: 4.5 | H19: 4.5 | I19: 6 | J19: 7.5 | K19: 6 | L19: 6 | M19: 4 | N19: 5 | O19: 5.5 | P19: 5.5 | Q19: 12.5 | R19: 16 | S19: 15 | T19: 18.5 | U19: 14 | V19: 19 | W19: 12 | X19: 23.5 | Y19: 12 | Z19: 21.5 | AA19: 12 | AB19: 31 | AC19: 16.5 | AD19: 37.5 | AE19: 21.5 | AF19: 23 | AG19: 23 | AH19: 27 | AI19: 26.5 | AJ19: 37 | AK19: 26 | AL19: 18
A20: Azerbaijan | B20: Azerbaïdjan | AI20: 0 | AJ20: 0.5 | AK20: 0 | AL20: 0
A21: Bosnia and Herzegovine | B21: Bosnie-Herzégovine | AI21: 0 | AJ21: 0 | AK21: 0 | AL21: 0
A22: Chypre | B22: Cyprus | C22: 0 | D22: 0 | E22: 0 | F22: 0 | G22: 0 | H22: 0 | I22: 0 | J22: 0 | K22: 0 | L22: 0 | M22: 0 | N22: 1 | O22: 1
A23: Croatie | B23: Croatia | J23: 0 | K23: 0 | L23: 1 | M23: 2.5 | N23: 2 | O23: 0.5 | P23: 0 | Q23: 0.5 | R23: 0.5 | S23: 0.5 | T23: 0.5 | U23: 0 | V23: 0 | W23: 0 | X23: 0 | Y23: 0
A24: Egypte | B24: Egypt | C24: 0 | D24: 0 | E24: 0 | F24: 0 | G24: 0 | H24: 0.5 | I24: 0 | J24: 0 | K24: 0 | L24: 1.5 | M24: 0.5 | N24: 0.5 | O24: 2 | P24: 0 | Q24: 0 | R24: 0.5 | S24: 2 | T24: 1 | U24: 3.5 | V24: 0 | W24: 0 | X24: 3 | Y24: 4 | Z24: 2 | AA24: 4 | AB24: 1 | AC24: 6.5 | AD24: 2.5 | AE24: 0.5 | AF24: 1 | AG24: 1 | AH24: 0 | AI24: 0.5 | AJ24: 0 | AK24: 0 | AL24: 1
A25: Géorgie | B25: Georgia | AE25: 0 | AF25: 0 | AG25: 0 | AH25: 0 | AI25: 0 | AJ25: 0 | AK25: 0 | AL25: 0
A26: Iran | B26: Iran | C26: 0 | D26: 0 | E26: 0 | F26: 0 | G26: 0 | H26: 0 | I26: 0 | J26: 0 | K26: 0 | L26: 0 | M26: 0 | N26: 0 | O26: 0 | P26: 0 | Q26: 0 | R26: 0 | S26: 0 | T26: 0 | U26: 0 | V26: 0 | W26: 0 | X26: 0 | Y26: 0 | Z26: 0 | AA26: 0 | AB26: 0 | AC26: 0 | AD26: 0 | AE26: 0 | AF26: 0 | AG26: 0 | AH26: 0 | AI26: 0 | AJ26: 0 | AK26: 0.5 | AL26: 0.5
A27: Irak | B27: Iraq | C27: 0 | D27: 0 | E27: 0 | F27: 0 | G27: 0 | H27: 0 | I27: 0 | J27: 0 | K27: 0 | L27: 0 | M27: 0 | N27: 0 | O27: 0 | P27: 0 | Q27: 0 | R27: 0 | S27: 0 | T27: 0 | U27: 0 | V27: 0 | W27: 0 | X27: 0 | Y27: 0 | Z27: 0 | AA27: 0 | AB27: 0 | AC27: 0 | AD27: 0 | AE27: 0 | AF27: 0 | AG27: 0 | AH27: 0 | AI27: 0 | AJ27: 0 | AK27: 0 | AL27: 0
A28: Israël | B28: Israel | C28: 0 | D28: 0 | E28: 0.5 | F28: 0 | G28: 0 | H28: 0.5 | I28: 0 | J28: 0 | K28: 0 | L28: 0 | M28: 0 | N28: 0 | O28: 0 | P28: 0 | Q28: 0 | R28: 0 | S28: 0.5 | T28: 0 | U28: 0 | V28: 0 | W28: 0 | X28: 0.5 | Y28: 0.5 | Z28: 0.5 | AA28: 0 | AB28: 0 | AC28: 0 | AD28: 0 | AE28: 0 | AF28: 0 | AG28: 0 | AH28: 0 | AI28: 0 | AJ28: 0 | AK28: 0 | AL28: 0
A29: Jordanie | B29: Jordan | C29: 0.5 | D29: 1 | E29: 1 | F29: 1 | G29: 0.5 | H29: 0.5 | I29: 0.5 | J29: 0 | K29: 1 | L29: 0.5 | M29: 0.5 | N29: 0.5 | O29: 1.5 | P29: 4 | Q29: 5 | R29: 3 | S29: 2 | T29: 2 | U29: 1.5 | V29: 2 | W29: 1 | X29: 1 | Y29: 1.5 | Z29: 9 | AA29: 0.5 | AB29: 0.5 | AC29: 0.5 | AD29: 0 | AE29: 0.5 | AF29: 0.5 | AG29: 3.5 | AH29: 4.5 | AI29: 3.5 | AJ29: 4 | AK29: 4.5 | AL29: 3
A30: Liban | B30: Lebanon | C30: 0 | D30: 0 | E30: 0.5 | F30: 0 | G30: 0.5 | H30: 2 | I30: 1.5 | J30: 0.5 | K30: 1.5 | L30: 0 | M30: 0 | N30: 0 | O30: 1.5 | P30: 1.5 | Q30: 1.5 | R30: 1 | S30: 3 | T30: 2.5 | U30: 2.5 | V30: 3 | W30: 3 | X30: 4 | Y30: 4 | Z30: 6 | AA30: 7.5 | AB30: 9.5 | AC30: 8 | AD30: 3 | AE30: 6.5 | AF30: 6.5 | AG30: 6.5 | AH30: 4.5 | AI30: 8 | AJ30: 3 | AK30: 7.5 | AL30: 4.5
A31: Libye | B31: Libya | C31: 0 | D31: 0 | E31: 0 | F31: 0 | G31: 0 | H31: 0 | I31: 0 | J31: 0 | K31: 0 | L31: 0 | M31: 0 | N31: 0 | O31: 0 | P31: 0 | Q31: 0.5 | R31: 0 | S31: 0 | T31: 0 | U31: 0 | V31: 0 | W31: 0 | X31: 0 | Y31: 0 | Z31: 2 | AA31: 0 | AB31: 0 | AC31: 0 | AD31: 0 | AE31: 0 | AF31: 0 | AG31: 0 | AH31: 0 | AI31: 0 | AJ31: 0 | AK31: 0 | AL31: 0
A32: Maroc | B32: Morocco | C32: 1.5 | D32: 5 | E32: 0.5 | F32: 0 | G32: 5 | H32: 11.5 | I32: 35 | J32: 7.5 | K32: 15.5 | L32: 0.5 | M32: 0 | N32: 0.5 | O32: 3 | P32: 20.5 | Q32: 31 | R32: 21 | S32: 4.5 | T32: 2 | U32: 3 | V32: 21 | W32: 30.5 | X32: 11 | Y32: 10 | Z32: 9.5 | AA32: 25 | AB32: 17 | AC32: 9 | AD32: 11 | AE32: 28 | AF32: 10.5 | AG32: 10 | AH32: 14.5 | AI32: 7 | AJ32: 9 | AK32: 3 | AL32: 7.5
A33: Montenegro | B33: Montenegro | C33: 0 | D33: 0 | E33: 0 | F33: 0 | G33: 0 | H33: 0 | I33: 0 | J33: 0 | K33: 0 | L33: 0 | M33: 0 | N33: 0 | O33: 0 | P33: 0 | Q33: 0 | R33: 0 | S33: 0 | T33: 0 | U33: 0 | V33: 0 | W33: 0 | X33: 0 | Y33: 0 | Z33: 0 | AA33: 0 | AB33: 0 | AC33: 0 | AD33: 0 | AE33: 0 | AF33: 0 | AG33: 0 | AH33: 0 | AI33: 0 | AJ33: 0 | AK33: 0 | AL33: 0
A34: Ouzbékistan | B34: Uzbekistan | AE34: 0 | AF34: 0 | AG34: 0 | AH34: 0 | AI34: 0 | AJ34: 0 | AK34: 0 | AL34: 0
A35: Palestine | B35: Palestine | E35: 11 | F35: 1 | G35: 4.5 | H35: 3.5 | I35: 4 | J35: 5 | K35: 2 | L35: 0 | M35: 2 | N35: 0 | O35: 0 | P35: 8 | Q35: 10 | R35: 10 | S35: 11.5 | T35: 0 | U35: 3 | V35: 0.5 | W35: 4 | X35: 3.5 | Y35: 3.5 | Z35: 4 | AA35: 6.5 | AB35: 4.5 | AC35: 6.5 | AD35: 4.5 | AE35: 2.5 | AF35: 8 | AG35: 6 | AH35: 7.5 | AI35: 8.5 | AJ35: 3.5 | AK35: 6 | AL35: 2
A36: Tunisie | B36: Tunisia | C36: 161.5 | D36: 96.5 | E36: 110 | F36: 178 | G36: 104 | H36: 26.5 | I36: 115 | J36: 117 | K36: 175 | L36: 112 | M36: 95 | N36: 22 | O36: 40 | P36: 209 | Q36: 98 | R36: 115.5 | S36: 175 | T36: 130 | U36: 142 | V36: 97 | W36: 108 | X36: 129.5 | Y36: 170 | Z36: 58 | AA36: 304 | AB36: 102.5 | AC36: 89.5 | AD36: 205 | AE36: 160 | AF36: 355 | AG36: 205 | AH36: 187 | AI36: 198.5 | AJ36: 199.5 | AK36: 275 | AL36: 300
A37: Turquie | B37: Türkiye | C37: 10 | D37: 10.5 | E37: 5.5 | F37: 9 | G37: 55 | H37: 19 | I37: 40.5 | J37: 35 | K37: 86 | L37: 16.5 | M37: 92 | N37: 28 | O37: 74 | P37: 46 | Q37: 93.5 | R37: 73 | S37: 45 | T37: 15 | U37: 31 | V37: 29.5 | W37: 12 | X37: 20 | Y37: 92 | Z37: 35 | AA37: 30 | AB37: 15 | AC37: 45 | AD37: 66 | AE37: 55 | AF37: 45 | AG37: 42 | AH37: 58 | AI37: 150 | AJ37: 69 | AK37: 160 | AL37: 100
A38: UE * | B38: EU * | C38: 146 | D38: 174 | E38: 161.5 | F38: 182.5 | G38: 182.5 | H38: 165 | I38: 220 | J38: 227 | K38: 208.5 | L38: 298.5 | M38: 291 | N38: 324.5 | O38: 313.5 | P38: 324.5 | Q38: 330.5 | R38: 310.5 | S38: 351 | T38: 357 | U38: 376 | V38: 444 | W38: 481 | X38: 555.5 | Y38: 491 | Z38: 600.5 | AA38: 508 | AB38: 573.5 | AC38: 558 | AD38: 563.5 | AE38: 648 | AF38: 746.5 | AG38: 804 | AH38: 820.5 | AI38: 602.5 | AJ38: 608.5 | AK38: 746.5 | AL38: 787
A39: Uruguay | B39: Uruguay | Z39: 0 | AA39: 0 | AB39: 0 | AC39: 0 | AD39: 0 | AE39: 0 | AF39: 1 | AG39: 0.5 | AH39: 0.5 | AI39: 0.5 | AJ39: 0.5 | AK39: 0 | AL39: 0
A41: TOTAL A | C41: =SUM(C16:C38) -> 323.5 | D41: =SUM(D16:D38) -> 292 | E41: =SUM(E16:E38) -> 296 | F41: =SUM(F16:F38) -> 375.5 | G41: =SUM(G16:G38) -> 356.5 | H41: =SUM(H17:H38) -> 233.5 | I41: =SUM(I16:I38) -> 422.5 | J41: =SUM(J16:J38) -> 399.5 | K41: =SUM(K16:K38) -> 495.5 | L41: =SUM(L16:L38) -> 436.5 | M41: =SUM(M16:M38) -> 487.5 | N41: =SUM(N16:N38) -> 384 | O41: =SUM(O16:O38) -> 442.5 | P41: =SUM(P16:P38) -> 619 | ... AA41: =SUM(AA16:AA38) -> 897.5 | AB41: =SUM(AB16:AB39) -> 754.5 | AC41: =SUM(AC16:AC39) -> 739.5 | AD41: =SUM(AD16:AD39) -> 893 | AE41: 922.5 | AF41: 1197 | AG41: 1102 | AH41: 1124.5 | AI41: 1011.5 | AJ41: =SUM(AJ16:AJ39) -> 940 | AK41: =SUM(AK16:AK39) -> 1232 | AL41: =SUM(AL16:AL39) -> 1226.5
A44: A. Saoudite | B44: Saudi Arabia | C44: 0 | D44: 0 | E44: 0 | F44: 0 | G44: 0 | H44: 0 | I44: 0 | J44: 0 | K44: 0 | L44: 0 | M44: 0 | N44: 0 | O44: 0 | P44: 0 | Q44: 0 | R44: 0 | S44: 0.5 | T44: 0.5 | U44: 0.5 | V44: 0.5 | W44: 0.5 | X44: 0.5 | Y44: 0.5 | Z44: 0.5 | AA44: 0.5 | AB44: 0.5 | AC44: 0.5 | AD44: 0.5 | AE44: 0.5 | AF44: 0 | AG44: 0.5
A45: Australie | B45: Australia | C45: 0 | D45: 0 | E45: 0 | F45: 0 | G45: 0 | H45: 0 | I45: 0 | J45: 0 | K45: 0 | L45: 0 | M45: 0 | N45: 0 | O45: 0 | P45: 0.5 | Q45: 1.5 | R45: 3.5 | S45: 2.5 | T45: 4 | U45: 6.5 | V45: 8 | W45: 6 | X45: 6.5 | Y45: 2.5 | Z45: 4.5 | AA45: 4.5 | AB45: 4 | AC45: 4.5 | AD45: 3 | AE45: 3 | AF45: 2.5 | AG45: 2 | AH45: 4 | AI45: 4.5 | AJ45: 2 | AK45: 2 | AL45: 2
A46: Brésil | B46: Brazil | C46: 0 | D46: 0 | E46: 0 | F46: 0 | G46: 0 | H46: 0 | I46: 0 | J46: 0 | K46: 0 | L46: 0 | M46: 0 | N46: 0 | O46: 0 | P46: 0 | Q46: 0 | R46: 0 | S46: 0 | T46: 0 | U46: 0 | W46: 0 | X46: 0 | Y46: 0 | Z46: 0 | AA46: 0 | AB46: 0 | AC46: 0 | AD46: 0 | AE46: 0 | AF46: 0 | AG46: 0 | AH46: 0 | AI46: 0 | AJ46: 0 | AK46: 0 | AL46: 0
A47: Canada | B47: Canada
A48: Chili | B48: Chile | C48: 0 | D48: 0 | E48: 0 | F48: 0 | G48: 0 | H48: 0 | I48: 0 | J48: 0 | K48: 0 | L48: 0 | M48: 0 | N48: 0 | O48: 0 | P48: 0 | Q48: 0 | R48: 0 | S48: 1 | T48: 1.5 | U48: 2 | V48: 3 | W48: 6.5 | X48: 10 | Y48: 10 | Z48: 10 | AA48: 14.5 | AB48: 10.5 | AC48: 13 | AD48: 14.5 | AE48: 12 | AF48: 15.5 | AG48: 13 | AH48: 16 | AI48: 16.5 | AJ48: 16 | AK48: 16.5 | AL48: 16.5
A49: China | B49: China
A50: Etats-Unis | B50: USA | C50: 3 | D50: 9 | E50: 2 | F50: 2 | G50: 7 | H50: 9 | I50: 8 | J50: 4.5 | K50: 6 | L50: 5.5 | M50: 3.5 | N50: 5 | O50: 9.5 | P50: 9 | Q50: 12 | R50: 10 | S50: 3 | T50: 3 | U50: 3 | V50: 2.5 | W50: 3 | X50: 4.5 | Y50: 6 | Z50: 5.5 | AA50: 6.5 | AB50: 7.5 | AC50: 8 | AD50: 8.5 | AE50: 6.5 | AF50: 3.5 | AG50: 4 | AH50: 3.5 | AI50: 5.5 | AJ50: 9 | AK50: 10 | AL50: 9
A51: Japon | B51: Japan
...

Sheet Con.
A2: CONSEIL OLÉICOLE INTERNATIONAL (NOV 2025)
A3: INTERNATIONAL OLIVE COUNCIL (NOV 2025)
A6: HUILES D'OLIVE - OLIVE OILS
A9: Tableau 4: CONSOMMATION (1.000 tm) - Table 4: CONSUMPTION (1,000 tonnes)
C12: 1990/91 | D12: 1991/92 | E12: 1992/93 | F12: 1993/94 | G12: 1994/95 | H12: 1995/96 | I12: 1996/97 | J12: 1997/98 | K12: 1998/9 | L12: 1999/0 | M12: 2000/1 | N12: 2001/2 | O12: 2002/3 | P12: 2003/4 | Q12: 2004/5 | R12: 2005/6 | S12: 2006/7 | T12: 2007/8 | U12: 2008/9 | V12: 2009/10 | W12: 2010/11 | X12: 2011/12 | Y12: 2012/13 | Z12: 2013/14 | AA12: 2014/15 | AB12: 2015/16 | AC12: 2016/17 | AD12: 2017/18 | AE12: 2018/19 | AF12: 2019/20 | AG12: 2020/21 | AH12: 2021/22 | AI12: 2022/23 | AJ12: 2023/24 | AK12: 2024/25 | AL12: 2025/26
AK13: (prov.) | AL13: (prev.)
C14: (1) | D14: (2) | E14: (3) | F14: (4) | G14: (5) | H14: (6) | I14: (7) | J14: (8) | K14: (9) | L14: (10) | M14: (11) | N14: (12) | O14: (13) | P14: (14) | Q14: (15) | R14: (16) | S14: (17) | T14: (18) | U14: (19) | V14: (20) | W14: (21) | X14: (22) | Y14: (23) | Z14: (24) | AA14: (25) | AB14: (26) | AC14: (27) | AD14: (28) | AE14: (29) | AF14: (30) | AG14: (31) | AH14: (32) | AI14: (33) | AJ14: (34) | AK14: (35) | AL14: (36)
A16: Albanie | B16: Albania | T16: 4.5 | U16: 7 | V16: 6 | W16: 9 | X16: 8 | Y16: 13 | Z16: 11.5 | AA16: 12.5 | AB16: 11.5 | AC16: 13 | AD16: 12.5 | AE16: 13.5 | AF16: 13 | AG16: 14.5 | AH16: 18 | AI16: 24 | AJ16: 26.5 | AK16: 23 | AL16: 23.5
A17: Algérie | B17: Algeria | C17: 7 | D17: 27 | E17: 30 | F17: 25 | G17: 17.5 | H17: 36 | I17: 50 | J17: 31.5 | K17: 44 | L17: 42 | M17: 26 | N17: 25 | O17: 21 | P17: 60 | Q17: 38 | R17: 35 | S17: 23 | T17: 25 | U17: 55 | V17: 33.5 | W17: 59 | X17: 42.5 | Y17: 60.5 | Z17: 48.5 | AA17: 65 | AB17: 80 | AC17: 67 | AD17: 82.5 | AE17: 92 | AF17: 115 | AG17: 80 | AH17: 95 | AI17: 75 | AJ17: 72 | AK17: 90.5 | AL17: 80.5
A18: A. Saoudite | B18: Saudi Arabia | AH18: 36.5 | AI18: 66 | AJ18: 55.5 | AK18: 35 | AL18: 40
A19: Argentine | B19: Argentina | C19: 4 | D19: 4 | E19: 4.5 | F19: 4 | G19: 3 | H19: 6 | I19: 8 | J19: 8 | K19: 8 | L19: 7 | M19: 6 | N19: 5.5 | O19: 5.5 | P19: 5.5 | Q19: 5 | R19: 5.5 | S19: 3 | T19: 7 | U19: 5 | V19: 5 | W19: 5.5 | X19: 6 | Y19: 6 | Z19: 6.5 | AA19: 6.5 | AB19: 7.5 | AC19: 7.5 | AD19: 8 | AE19: 7.5 | AF19: 7.5 | AG19: 7.5 | AH19: 7.5 | AI19: 7.5 | AJ19: 7.5 | AK19: 7.5 | AL19: 7.5
A20: Azerbaijan | B20: Azerbaïdjan | AI20: 2.5 | AJ20: 1 | AK20: 2.5 | AL20: 2
A21: Bosnia and Herzegovine | B21: Bosnie-Herzégovine | AI21: 0.5 | AJ21: 0.5 | AK21: 0.5 | AL21: 0.5
A22: Chypre | B22: Cyprus | C22: 2 | D22: 2 | E22: 2 | F22: 3 | G22: 3 | H22: 3 | I22: 2.5 | J22: 2 | K22: 2.5 | L22: 4 | M22: 5 | N22: 5.5 | O22: 6
A23: Croatie | B23: Croatia | J23: 2 | K23: 4 | L23: 8.5 | M23: 6.5 | N23: 5 | O23: 6.5 | P23: 4 | Q23: 4.5 | R23: 5 | S23: 5 | T23: 5 | U23: 7 | V23: 6.5 | W23: 7 | X23: 6 | Y23: 6
A24: Egypte | B24: Egypt | C24: 1.5 | D24: 1 | E24: 2 | F24: 1.5 | G24: 2 | H24: 2.5 | I24: 1 | J24: 1 | K24: 1 | L24: 1.5 | M24: 1 | N24: 1.5 | O24: 3.5 | P24: 2 | Q24: 2.5 | R24: 2 | S24: 8 | T24: 7 | U24: 5 | V24: 7 | W24: 5 | X24: 7.5 | Y24: 12 | Z24: 18.5 | AA24: 20 | AB24: 16.5 | AC24: 22 | AD24: 40 | AE24: 45 | AF24: 43 | AG24: 42 | AH24: 45 | AI24: 54 | AJ24: 50 | AK24: 45 | AL24: 50
A25: Géorgie | B25: Georgia | AE25: 0.5 | AF25: 0.5 | AG25: 0.5 | AH25: 0.5 | AI25: 0.5 | AJ25: 0.5 | AK25: 0.5 | AL25: 0.5
A26: Iran | B26: Iran | C26: 2.5 | D26: 3 | E26: 2.5 | F26: 3.5 | G26: 2.5 | H26: 5 | I26: 3.5 | J26: 4 | K26: 2.5 | L26: 2.5 | M26: 3 | N26: 2 | O26: 1.5 | P26: 3.5 | Q26: 5 | R26: 6.5 | S26: 5.5 | T26: 7.5 | U26: 7 | V26: 6.5 | W26: 7.5 | X26: 11 | Y26: 8.5 | Z26: 10 | AA26: 9 | AB26: 10.5 | AC26: 8 | AD26: 10.5 | AE26: 14.5 | AF26: 11 | AG26: 11.5 | AH26: 17 | AI26: 14.5 | AJ26: 14.5 | AK26: 13 | AL26: 17
A27: Irak | B27: Iraq | R27: 0 | S27: 0 | T27: 0 | U27: 0 | V27: 8.5 | W27: 6 | X27: 6 | Y27: 6 | Z27: 6 | AA27: 1.5 | AB27: 1.5 | AC27: 1.5 | AD27: 1.5 | AE27: 1.5 | AF27: 1.5 | AG27: 1 | AH27: 1 | AI27: 1.5 | AJ27: 1.5 | AK27: 2 | AL27: 2
A28: Israël | B28: Israel | C28: 6 | D28: 5 | E28: 5 | F28: 4.5 | G28: 7 | H28: 7.5 | I28: 7.5 | J28: 6.5 | K28: 9.5 | L28: 12.5 | M28: 13.5 | N28: 14.5 | O28: 15 | P28: 13.5 | Q28: 16 | R28: 16.5 | S28: 15 | T28: 16 | U28: 17 | V28: 16.5 | W28: 17 | X28: 15.5 | Y28: 19.5 | Z28: 20 | AA28: 20 | AB28: 20 | AC28: 21 | AD28: 21 | AE28: 25 | AF28: 28 | AG28: 25 | AH28: 24 | AI28: 31 | AJ28: 33 | AK28: 30 | AL28: 31.5
